Workbook

Sheet 字段
B2: 拍卖数据 | D2: 抵质押物台账
B4: 资产所有人 | D4: 序号
B5: 竞拍人 | D5: 资产编号
B6: 证件号码 | D6: 是否终极处置
B7: 拍品名称 | D7: 债务人名称
B8: 省 | D8: 行业
B9: 市 | D9: 债权本金余额（万元）
B10: 县/区 | D10: 债权利息余额（万元）
B11: 地址 | D11: 代垫费用余额（万元）
B12: 拍卖轮次 | D12: 孳息余额（万元）
B13: 成交状态 | D13: 资产原值余额合计（万元）
B14: 类型 | D14: 担保形式
... B41: 源网站链接 | D41: 法定优先受偿权情况
D42: 法定优先受偿权金额（万元）
D43: 其他说明
D44: 管户经理
D45: 分公司
D46: 所属项目
D47: 所属项目名称
D48: 投放日期
D49: 是否需要补录数据
D50: 剔除重复押品逻辑
D51: 考虑优先受偿和顺位剔除重复押品

Sheet 拍卖数据
A1: 新报表
A3: 资产所有人 | B3: 竞拍人 | C3: 证件号码 | D3: 拍品名称 | E3: 省 | F3: 市 | G3: 县/区 | H3: 地址 | I3: 拍卖轮次 | J3: 成交状态 | K3: 类型 | L3: 起拍价格（单位：元） | M3: 评估价（单位：元） | N3: 成交价 | O3: 房产类型 | P3: 建筑面积(单位:平方米) | Q3: 土地面积(单位:平方米) | R3: 是否腾空 | S3: 共有情况 | T3: 是否瑕疵 | U3: 朝向 | V3: 户型 | W3: 是否租赁 | X3: 装修程度 | Y3: 土地用途 | Z3: 总楼层 | AA3: 所在楼层 | AB3: 是否查封 | AC3: 使用权终止日期 | AD3: 权利来源 | AE3: 建成年代 | AF3: 房屋结构 | AG3: 债权本金（单位：元） | AH3: 未尝利息（单位：元） | AI3: 债权总额（单位：元） | AJ3: 担保方式 | AK3: 拍卖结束时间 | AL3: 源网站链接 | AM3: 竞拍人长度 | AN3: 机构/个人
B4: 孙艳红 | D4: 合肥市庐阳区临泉路7366号橡树湾7幢2404室 | E4: 安徽省 | F4: 合肥市 | G4: 庐阳区 | H4: 安徽省合肥市庐阳区临泉路7366号橡树湾7幢2404室 | I4: 变卖 | J4: 成交 | K4: 房产 | L4: 2446393 | M4: 3197900 | N4: 2446393 | O4: 居住用房 | P4: 130.09 | Q4: 0 | T4: 是 | W4: 未知 | Y4: 住宅 | Z4: 35 | AA4: 24 | AB4: 是 | AE4: 2013 | AF4: 钢混结构 | AK4: 45597.805 | AL4: https://zc-item.taobao.com/auction/824704626523.htm | AM4: =LEN(B4) -> 3 | AN4: 个人
B5: 王友勤 | D5: 安庆市迎江区华中西路98-124#2单元604室（实勘为192号1号楼）房产 | E5: 安徽省 | F5: 安庆市 | G5: 迎江区 | H5: 安徽省安庆市迎江区华中西路98-124#2单元604室（实勘为192号1号楼） | I5: 变卖 | J5: 成交 | K5: 房产 | L5: 310856 | M5: 555100 | N5: 310856 | O5: 居住用房 | P5: 93.06 | Q5: 0 | T5: 是 | U5: 南北 | W5: 否 | X5: 精装，外墙真石漆，钢制入户门，铝合金窗；室内地面地砖（卧室木地板），墙面乳胶漆和墙布、石膏板吊顶、设备较齐全（定制橱柜、燃气灶、浴霸、马桶、淋雨、置物架） | Y5: 住宅 | Z5: 6 | AA5: 6 | AB5: 未知 | AF5: 混合结构 | AK5: 45603.341 | AL5: https://zc-item.taobao.com/auction/827369118883.htm | AM5: =LEN(B5) -> 3 | AN5: 个人
B6: 余泉 | C6: ****0213 | D6: 安徽省颍上县慎城镇城北新区颍阳路北侧荐贤路西侧在水一方11#楼2-403号 | E6: 安徽省 | F6: 阜阳市 | G6: 颍上县 | H6: 安徽省阜阳市颍上县慎城镇城北新区颍阳路北侧荐贤路西侧在水一方11#楼2-403号 | I6: 变卖 | J6: 成交 | K6: 房产 | L6: 354304 | M6: 553600 | N6: 354304 | O6: 居住用房 | P6: 118.26 | Q6: 0 | T6: 未知 | W6: 未知 | Y6: 成套住宅 | Z6: 6 | AA6: 4 | AB6: 是 | AD6: 不动产权证书号：99053760 | AK6: 45606.481 | AL6: http://paimai.jd.com/307426302 | AM6: =LEN(B6) -> 2 | AN6: 个人
B7: 朱佳琳 | D7: 芜湖市弋江区金玺商业广场裙楼B202室房产 | E7: 安徽省 | F7: 芜湖市 | G7: 弋江区 | H7: 安徽省芜湖市弋江区金玺商业广场裙楼B202室房产 | I7: 变卖 | J7: 成交 | K7: 房产 | L7: 2826571 | M7: 5047447 | N7: 2826571 | O7: 商业用房 | P7: 835.67 | Q7: 0 | T7: 未知 | W7: 未知 | Z7: 21 | AA7: 2 | AB7: 是 | AF7: 钢混结构 | AK7: 45616.419 | AL7: https://zc-item.taobao.com/auction/833128405681.htm | AM7: =LEN(B7) -> 3 | AN7: 个人
B8: 徐婉豪 | D8: 太和县城关镇侯沟南侧、椿樱大道东侧、解放西路北侧西城首府B2号楼102户 | E8: 安徽省 | F8: 阜阳市 | G8: 太和县 | H8: 安徽省阜阳市太和县城关镇侯沟南侧、椿樱大道东侧、解放西路北侧西城首府B2号楼102户 | I8: 变卖 | J8: 成交 | K8: 房产 | L8: 767686 | M8: 950695 | N8: 849686 | O8: 居住用房 | P8: 136.83 | Q8: 0 | S8: 共同共有 | T8: 未知 | W8: 否 | Y8: 住宅 | Z8: 31 | AA8: 1 | AB8: 是 | AF8: 混合结构 | AK8: 45603.549 | AL8: https://zc-item.taobao.com/auction/833884836836.htm | AM8: =LEN(B8) -> 3 | AN8: 个人
B9: 戚雪莲 | D9: 合肥市长丰县双凤开发区蒙城北路与梅登路交口御景嘉苑15幢901室 | E9: 安徽省 | F9: 合肥市 | G9: 长丰县 | H9: 安徽省合肥市长丰县合肥市长丰县双凤开发区蒙城北路与梅登路交口御景嘉苑15幢901室 | I9: 变卖 | J9: 成交 | K9: 房产 | L9: 830674 | M9: 1297927 | N9: 830674 | O9: 居住用房 | P9: 117.58 | Q9: 0 | T9: 是 | W9: 否 | Y9: 住宅 | Z9: 28 | AA9: 9 | AB9: 是 | AC9: 2083-5-1 | AE9: 2016-10-17 | AK9: 45597.375 | AL9: https://zc-item.taobao.com/auction/834507454051.htm | AM9: =LEN(B9) -> 3 | AN9: 个人
B10: 李仕保 | D10: 安徽省六安市霍邱县城关镇锦绣·壹号院3幢3201室 | E10: 安徽省 | F10: 六安市 | G10: 霍邱县 | H10: 安徽省六安市霍邱县城关镇锦绣·壹号院3幢3201室 | I10: 变卖 | J10: 成交 | K10: 房产 | L10: 488608 | M10: 642906 | N10: 488608 | O10: 居住用房 | P10: 122.21 | Q10: 0 | T10: 未知 | W10: 未知 | Z10: 0 | AA10: 0 | AB10: 是 | AF10: 钢混结构 | AK10: 45601.397 | AL10: https://zc-item.taobao.com/auction/826758013487.htm | AM10: =LEN(B10) -> 3 | AN10: 个人
B11: 吴梅芳 | D11: 旌德县白地镇金玉苑小区6幢503室住宅房地产 | E11: 安徽省 | F11: 宣城市 | G11: 旌德县 | H11: 安徽省宣城市旌德县白地镇金玉苑小区6幢503室住宅房地产 | I11: 变卖 | J11: 成交 | K11: 房产 | L11: 213960 | M11: 370864 | N11: 213960 | O11: 居住用房 | P11: 142.64 | Q11: 0 | T11: 未知 | W11: 否 | Y11: 住宅 | Z11: 6 | AA11: 5 | AB11: 是 | AD11: 司法裁定 | AK11: 45619.668 | AL11: https://zc-item.taobao.com/auction/833431254001.htm | AM11: =LEN(B11) -> 3 | AN11: 个人
B12: 吴梅芳 | D12: 旌德县白地镇金玉苑小区6幢602室住宅房地产 | E12: 安徽省 | F12: 宣城市 | G12: 旌德县 | H12: 安徽省宣城市旌德县白地镇金玉苑小区6幢602室住宅房地产 | I12: 变卖 | J12: 成交 | K12: 房产 | L12: 166665 | M12: 277775 | N12: 166665 | O12: 居住用房 | P12: 111.11 | Q12: 0 | T12: 未知 | W12: 否 | Y12: 住宅 | Z12: 6 | AA12: 6 | AB12: 是 | AD12: 司法裁定 | AK12: 45619.675 | AL12: https://zc-item.taobao.com/auction/833433406170.htm | AM12: =LEN(B12) -> 3 | AN12: 个人
B13: 余杨 | D13: 泾县泾川镇环城南路秀江南8幢2-601室 | E13: 安徽省 | F13: 宣城市 | G13: 泾县 | H13: 安徽省宣城市泾县泾川镇环城南路秀江南8幢2-601室 | I13: 变卖 | J13: 成交 | K13: 房产 | L13: 341000 | M13: 607800 | N13: 341000 | O13: 居住用房 | P13: 119.1 | Q13: 0 | T13: 未知 | W13: 未知 | Y13: 住宅 | Z13: 6 | AA13: 6 | AB13: 是 | AE13: 2007 | AF13: 混合结构 | AK13: 45617.443 | AL13: https://zc-item.taobao.com/auction/833433358068.htm | AM13: =LEN(B13) -> 2 | AN13: 个人
B14: 吴梅芳 | D14: 旌德县白地镇金玉苑小区12幢501室住宅房地产 | E14: 安徽省 | F14: 宣城市 | G14: 旌德县 | H14: 安徽省宣城市旌德县白地镇金玉苑小区12幢501室住宅房地产 | I14: 变卖 | J14: 成交 | K14: 房产 | L14: 204885 | M14: 341475 | N14: 204885 | O14: 居住用房 | P14: 136.59 | Q14: 0 | T14: 未知 | W14: 否 | Y14: 住宅 | Z14: 5 | AA14: 4 | AB14: 是 | AD14: 司法裁定 | AK14: 45619.674 | AL14: https://zc-item.taobao.com/auction/833424382597.htm | AM14: =LEN(B14) -> 3 | AN14: 个人
B15: 吴梅芳 | D15: 旌德县白地镇金玉苑小区12幢505室住宅房地产 | E15: 安徽省 | F15: 宣城市 | G15: 旌德县 | H15: 安徽省宣城市旌德县白地镇金玉苑小区12幢505室住宅房地产 | I15: 变卖 | J15: 成交 | K15: 房产 | L15: 157830 | M15: 263050 | N15: 157830 | O15: 居住用房 | P15: 105.22 | Q15: 0 | T15: 未知 | W15: 否 | Y15: 住宅 | Z15: 5 | AA15: 4 | AB15: 是 | AD15: 司法裁定 | AK15: 45619.674 | AL15: https://zc-item.taobao.com/auction/833442026058.htm | AM15: =LEN(B15) -> 3 | AN15: 个人
B16: 吴梅芳 | D16: 旌德县白地镇金玉苑小区12幢503室住宅房地产 | E16: 安徽省 | F16: 宣城市 | G16: 旌德县 | H16: 安徽省宣城市旌德县白地镇金玉苑小区12幢503室住宅房地产 | I16: 变卖 | J16: 成交 | K16: 房产 | L16: 170460 | M16: 284100 | N16: 170460 | O16: 居住用房 | P16: 113.64 | Q16: 0 | T16: 未知 | W16: 否 | Y16: 住宅 | Z16: 5 | AA16: 4 | AB16: 是 | AD16: 司法裁定 | AK16: 45619.674 | AL16: https://zc-item.taobao.com/auction/833438958272.htm | AM16: =LEN(B16) -> 3 | AN16: 个人
B17: 吴梅芳 | D17: 旌德县白地镇金玉苑小区6幢603室住宅房地产 | E17: 安徽省 | F17: 宣城市 | G17: 旌德县 | H17: 安徽省宣城市旌德县白地镇金玉苑小区6幢603室住宅房地产 | I17: 变卖 | J17: 成交 | K17: 房产 | L17: 143055 | M17: 238425 | N17: 143055 | O17: 居住用房 | P17: 95.37 | Q17: 0 | T17: 未知 | W17: 否 | Y17: 住宅 | Z17: 6 | AA17: 6 | AB17: 是 | AD17: 司法裁定 | AK17: 45619.675 | AL17: https://zc-item.taobao.com/auction/833809928635.htm | AM17: =LEN(B17) -> 3 | AN17: 个人
B18: 吴梅芳 | D18: 旌德县白地镇金玉苑小区6幢502室住宅房地产 | E18: 安徽省 | F18: 宣城市 | G18: 旌德县 | H18: 安徽省宣城市旌德县白地镇金玉苑小区6幢502室住宅房地产 | I18: 变卖 | J18: 成交 | K18: 房产 | L18: 209490 | M18: 363116 | N18: 209490 | O18: 居住用房 | P18: 139.66 | Q18: 0 | T18: 未知 | W18: 否 | Y18: 住宅 | Z18: 6 | AA18: 5 | AB18: 是 | AD18: 司法裁定 | AK18: 45619.667 | AL18: https://zc-item.taobao.com/auction/833213543614.htm | AM18: =LEN(B18) -> 3 | AN18: 个人
B19: 周金娣 | D19: 滁州市滁宁大道1998号碧桂园.花语岸15幢1单元1602室的不动产 | E19: 安徽省 | F19: 滁州市 | G19: 南谯区 | H19: 安徽省滁州市南谯区花语岸 | I19: 变卖 | J19: 成交 | K19: 房产 | L19: 300000 | M19: 350000 | N19: 300000 | O19: 居住用房 | P19: 119.61 | Q19: 0 | T19: 是 | W19: 否 | Z19: 0 | AA19: 1 | AB19: 是 | AD19: 司法裁定 | AK19: 45603.527 | AL19: https://zc-item.taobao.com/auction/828721080522.htm | AM19: =LEN(B19) -> 3 | AN19: 个人
B20: 夏佐茂 | D20: 池州绿地城二期紫荆苑小区B15#楼108、108复式一、108复式二 | E20: 安徽省 | F20: 池州市 | G20: 贵池区 | H20: 安徽省池州市贵池区池州绿地城二期紫荆苑小区B15#楼108、108复式一、108复式二 | I20: 变卖 | J20: 成交 | K20: 房产 | L20: 1071612 | M20: 1400800 | N20: 1071612 | O20: 居住用房 | P20: 158.07 | Q20: 0 | T20: 是 | W20: 否 | Y20: 城镇住宅用地 | Z20: 3 | AA20: 1 | AB20: 是 | AC20: 2089-12-29 | AE20: 2024 | AF20: 钢混结构 | AK20: 45618.571 | AL20: https://zc-item.taobao.com/auction/833984135138.htm | AM20: =LEN(B20) -> 3 | AN20: 个人
B21: 夏佐茂 | D21: 池州市贵池区池州绿地城二期紫荆苑小区B5#楼104、104复式一、104复式二 | E21: 安徽省 | F21: 池州市 | G21: 贵池区 | H21: 安徽省池州市贵池区池州绿地城二期紫荆苑小区B5#楼104、104复式一、104复式二 | I21: 变卖 | J21: 成交 | K21: 房产 | L21: 1068323 | M21: 1396500 | N21: 1068323 | O21: 居住用房 | P21: 157.58 | Q21: 0 | T21: 是 | W21: 否 | Y21: 城镇住宅用地 | Z21: 3 | AA21: 1 | AB21: 是 | AC21: 2089-12-29 | AE21: 2024 | AF21: 钢混结构 | AK21: 45618.567 | AL21: https://zc-item.taobao.com/auction/834436773952.htm | AM21: =LEN(B21) -> 3 | AN21: 个人
B22: 夏佐茂 | D22: 池州绿地城二期紫荆苑小区B15#楼104、104复式一、104复式二 | E22: 安徽省 | F22: 池州市 | G22: 贵池区 | H22: 安徽省池州市贵池区池州绿地城二期紫荆苑小区B15#楼104、104复式一、104复式二 | I22: 变卖 | J22: 成交 | K22: 房产 | L22: 1071612 | M22: 1400800 | N22: 1071612 | O22: 居住用房 | P22: 158.07 | Q22: 0 | T22: 是 | W22: 否 | Y22: 城镇住宅用地 | Z22: 3 | AA22: 1 | AB22: 是 | AC22: 2089-12-29 | AE22: 2024 | AF22: 钢混结构 | AK22: 45618.573 | AL22: https://zc-item.taobao.com/auction/833984159777.htm | AM22: =LEN(B22) -> 3 | AN22: 个人
B23: 钱俊 | D23: 合肥市蜀山区长江西路844号瑞园小区1幢2101室 | E23: 安徽省 | F23: 合肥市 | G23: 蜀山区 | H23: 安徽省合肥市蜀山区合肥市蜀山区长江西路844号瑞园小区1幢2101室 | I23: 变卖 | J23: 成交 | K23: 房产 | L23: 2214012 | M23: 2894132 | N23: 2214012 | O23: 居住用房 | P23: 198.6 | Q23: 0 | T23: 是 | W23: 否 | Y23: 成套住宅 | Z23: 25 | AA23: 21 | AB23: 是 | AK23: 45609.457 | AL23: https://zc-item.taobao.com/auction/829607633449.htm | AM23: =LEN(B23) -> 2 | AN23: 个人
B24: 蔡贞 | D24: 宿州市银河一路南侧瞰景苑小区4#楼0601室(附赠阁楼) | E24: 安徽省 | F24: 宿州市 | G24: 埇桥区 | H24: 安徽省宿州市埇桥区宿州市银河一路南侧瞰景苑小区4#楼0601室(附赠阁楼) | I24: 变卖 | J24: 成交 | K24: 房产 | L24: 646687 | M24: 756359 | N24: 646687 | O24: 居住用房 | P24: 129.27 | Q24: 0 | T24: 是 | W24: 未知 | Y24: 成套住宅 | Z24: 6 | AA24: 6 | AB24: 是 | AF24: 混合结构 | AK24: 45616.388 | AL24: https://zc-item.taobao.com/auction/834525651870.htm | AM24: =LEN(B24) -> 2 | AN24: 个人
B25: 周凤 | D25: 芜湖市鸠江区恒大华府30#楼2单元102室 | E25: 安徽省 | F25: 芜湖市 | G25: 鸠江区 | H25: 安徽省芜湖市鸠江区恒大华府30#楼2单元102室 | I25: 变卖 | J25: 成交 | K25: 房产 | L25: 950418 | M25: 1508598 | N25: 950418 | O25: 居住用房 | P25: 125.57 | Q25: 0 | T25: 未知 | W25: 否 | X25: 简装 | Z25: 0 | AA25: 0 | AB25: 是 | AK25: 45626.906 | AL25: https://zc-item.taobao.com/auction/835195676834.htm | AM25: =LEN(B25) -> 2 | AN25: 个人
B26: 李玲 | D26: 安徽省蚌埠市怀远县荆山镇禹王东路89号江山御景C区C9号楼S111店面 | E26: 安徽省 | F26: 蚌埠市 | G26: 怀远县 | H26: 安徽省蚌埠市怀远县荆山镇禹王东路89号江山御景C区C9号楼S111店面 | I26: 变卖 | J26: 成交 | K26: 房产 | L26: 484139 | M26: 864533 | N26: 484139 | O26: 商业用房 | P26: 96.3 | Q26: 0 | T26: 未知 | W26: 是 | Y26: 店面 | Z26: 0 | AA26: 0 | AB26: 是 | AD26: 司法裁定 | AK26: 45625.682 | AL26: https://zc-item.taobao.com/auction/835262040664.htm | AM26: =LEN(B26) -> 2 | AN26: 个人
B27: 李玲 | D27: 安徽省蚌埠市怀远县荆山镇禹王东路89号江山御景A区A5号楼S109店面 | E27: 安徽省 | F27: 蚌埠市 | G27: 怀远县 | H27: 安徽省蚌埠市怀远县荆山镇禹王东路89号江山御景A区A5号楼S109店面 | I27: 变卖 | J27: 成交 | K27: 房产 | L27: 650176 | M27: 1161029 | N27: 650176 | O27: 商业用房 | P27: 81.86 | Q27: 0 | T27: 未知 | W27: 是 | Y27: 店面 | Z27: 0 | AA27: 0 | AB27: 是 | AD27: 司法裁定 | AK27: 45625.699 | AL27: https://zc-item.taobao.com/auction/835267552711.htm | AM27: =LEN(B27) -> 2 | AN27: 个人
B28: 李玲 | D28: 安徽省蚌埠市怀远县荆山镇禹王东路89号江山御景C区C9号楼S117店面 | E28: 安徽省 | F28: 蚌埠市 | G28: 怀远县 | H28: 安徽省蚌埠市怀远县荆山镇禹王东路89号江山御景C区C9号楼S117店面 | I28: 变卖 | J28: 成交 | K28: 房产 | L28: 478156 | M28: 853850 | N28: 478156 | O28: 商业用房 | P28: 95.11 | Q28: 0 | T28: 未知 | W28: 是 | Y28: 店面 | Z28: 0 | AA28: 0 | AB28: 是 | AD28: 司法裁定 | AK28: 45625.693 | AL28: https://zc-item.taobao.com/auction/835088749486.htm | AM28: =LEN(B28) -> 2 | AN28: 个人
B29: 李玲 | D29: 安徽省蚌埠市怀远县荆山镇禹王东路89号江山御景C区C9号楼S105店面 | E29: 安徽省 | F29: 蚌埠市 | G29: 怀远县 | H29: 安徽省蚌埠市怀远县荆山镇禹王东路89号江山御景C区C9号楼S105店面 | I29: 变卖 | J29: 成交 | K29: 房产 | L29: 191704 | M29: 342329 | N29: 191704 | O29: 商业用房 | P29: 28.77 | Q29: 0 | T29: 未知 | W29: 是 | Y29: 店面 | Z29: 0 | AA29: 0 | AB29: 是 | AD29: 司法裁定 | AK29: 45625.648 | AL29: https://zc-item.taobao.com/auction/835259372624.htm | AM29: =LEN(B29) -> 2 | AN29: 个人
B30: 李玲 | D30: 安徽省蚌埠市怀远县荆山镇禹王东路89号江山御景C区C9号楼S115店面 | E30: 安徽省 | F30: 蚌埠市 | G30: 怀远县 | H30: 安徽省蚌埠市怀远县荆山镇禹王东路89号江山御景C区C9号楼S115店面 | I30: 变卖 | J30: 成交 | K30: 房产 | L30: 304798 | M30: 544282 | N30: 304798 | O30: 商业用房 | P30: 50.82 | Q30: 0 | T30: 未知 | W30: 是 | Y30: 店面 | Z30: 0 | AA30: 0 | AB30: 是 | AD30: 司法裁定 | AK30: 45625.688 | AL30: https://zc-item.taobao.com/auction/834843234708.htm | AM30: =LEN(B30) -> 2 | AN30: 个人
B31: 李玲 | D31: 安徽省蚌埠市怀远县荆山镇禹王东路89号江山御景A区A-SY1号楼S102店面 | E31: 安徽省 | F31: 蚌埠市 | G31: 怀远县 | H31: 安徽省蚌埠市怀远县荆山镇禹王东路89号江山御景A区A-SY1号楼S102店面 | I31: 变卖 | J31: 成交 | K31: 房产 | L31: 332775 | M31: 594240 | N31: 332775 | O31: 商业用房 | P31: 42.85 | Q31: 0 | T31: 未知 | W31: 是 | Y31: 店面 | Z31: 0 | AA31: 0 | AB31: 是 | AD31: 司法裁定 | AK31: 45625.695 | AL31: https://zc-item.taobao.com/auction/834847134441.htm | AM31: =LEN(B31) -> 2 | AN31: 个人
B32: 李玲 | D32: 安徽省蚌埠市怀远县荆山镇禹王东路89号江山御景C区C6号楼S115店面 | E32: 安徽省 | F32: 蚌埠市 | G32: 怀远县 | H32: 安徽省蚌埠市怀远县荆山镇禹王东路89号江山御景C区C6号楼S115店面 | I32: 变卖 | J32: 成交 | K32: 房产 | L32: 272938 | M32: 487389 | N32: 272938 | O32: 商业用房 | P32: 42.92 | Q32: 0 | T32: 未知 | W32: 是 | Y32: 店面 | Z32: 0 | AA32: 0 | AB32: 是 | AD32: 司法裁定 | AK32: 45625.669 | AL32: https://zc-item.taobao.com/auction/834632351926.htm | AM32: =LEN(B32) -> 2 | AN32: 个人
B33: 李玲 | D33: 安徽省蚌埠市怀远县荆山镇禹王东路89号江山御景C区C9号楼S102店面 | E33: 安徽省 | F33: 蚌埠市 | G33: 怀远县 | H33: 安徽省蚌埠市怀远县荆山镇禹王东路89号江山御景C区C9号楼S102店面 | I33: 变卖 | J33: 成交 | K33: 房产 | L33: 330934 | M33: 590953 | N33: 330934 | O33: 商业用房 | P33: 52.04 | Q33: 0 | T33: 未知 | W33: 是 | Y33: 店面 | Z33: 0 | AA33: 0 | AB33: 是 | AD33: 司法裁定 | AK33: 45625.675 | AL33: https://zc-item.taobao.com/auction/834634691702.htm | AM33: =LEN(B33) -> 2 | AN33: 个人
B34: 李玲 | D34: 安徽省蚌埠市怀远县荆山镇禹王东路89号江山御景C区C9号楼S112店面 | E34: 安徽省 | F34: 蚌埠市 | G34: 怀远县 | H34: 安徽省蚌埠市怀远县荆山镇禹王东路89号江山御景C区C9号楼S112店面 | I34: 变卖 | J34: 成交 | K34: 房产 | L34: 304798 | M34: 544282 | N34: 304798 | O34: 商业用房 | P34: 50.82 | Q34: 0 | T34: 未知 | W34: 是 | Y34: 店面 | Z34: 0 | AA34: 0 | AB34: 是 | AD34: 司法裁定 | AK34: 45625.684 | AL34: https://zc-item.taobao.com/auction/834634431818.htm | AM34: =LEN(B34) -> 2 | AN34: 个人
B35: 李玲 | D35: 安徽省蚌埠市怀远县荆山镇禹王东路89号江山御景C区C6号楼S112店面 | E35: 安徽省 | F35: 蚌埠市 | G35: 怀远县 | H35: 安徽省蚌埠市怀远县荆山镇禹王东路89号江山御景C区C6号楼S112店面 | I35: 变卖 | J35: 成交 | K35: 房产 | L35: 284766 | M35: 508510 | N35: 284766 | O35: 商业用房 | P35: 44.78 | Q35: 0 | T35: 未知 | W35: 是 | Y35: 店面 | Z35: 0 | AA35: 0 | AB35: 是 | AD35: 司法裁定 | AK35: 45625.628 | AL35: https://zc-item.taobao.com/auction/834841482701.htm | AM35: =LEN(B35) -> 2 | AN35: 个人
B36: 李玲 | D36: 安徽省蚌埠市怀远县荆山镇禹王东路89号江山御景C区C9号楼S113店面 | E36: 安徽省 | F36: 蚌埠市 | G36: 怀远县 | H36: 安徽省蚌埠市怀远县荆山镇禹王东路89号江山御景C区C9号楼S113店面 | I36: 变卖 | J36: 成交 | K36: 房产 | L36: 304798 | M36: 544282 | N36: 304798 | O36: 商业用房 | P36: 50.82 | Q36: 0 | T36: 未知 | W36: 是 | Y36: 店面 | Z36: 0 | AA36: 0 | AB36: 是 | AD36: 司法裁定 | AK36: 45625.686 | AL36: https://zc-item.taobao.com/auction/834635095782.htm | AM36: =LEN(B36) -> 2 | AN36: 个人
B37: 程余 | D37: 广德市大观国际105号、106号商铺 | E37: 安徽省 | F37: 宣城市 | G37: 广德市 | H37: 安徽省宣城市广德市大观国际105号、106号商铺 | I37: 变卖 | J37: 成交 | K37: 房产 | L37: 1493688 | M37: 2667300 | N37: 1493688 | O37: 商业用房 | P37: 199.66 | Q37: 0 | T37: 未知 | W37: 未知 | Y37: 商业服务 | Z37: 4 | AA37: 1 | AB37: 是 | AC37: 2053-9-10 | AD37: 司法裁定 | AF37: 钢混结构 | AK37: 45656.25 | AL37: https://zc-item.taobao.com/auction/841829618732.htm | AM37: =LEN(B37) -> 2 | AN37: 个人
B38: 张星 | C38: ****1824 | D38: 安徽省蚌埠市蚌山区荣盛华府11号楼1单元11层2号 | E38: 安徽省 | F38: 蚌埠市 | G38: 蚌山区 | H38: 安徽省蚌埠市蚌山区荣盛华府11号楼1单元11层2号 | I38: 一拍 | J38: 成交 | K38: 房产 | L38: 1492920.4 | M38: 2132743.5 | N38: 2542920.5 | O38: 居住用房 | P38: 219.17 | Q38: 0 | T38: 是 | U38: 南 | W38: 未知 | Y38: 住宅 | Z38: 19 | AA38: 11 | AB38: 是 | AK38: 45601.494 | AL38: http://paimai.jd.com/307562181 | AM38: =LEN(B38) -> 2 | AN38: 个人
B39: 曾萧雅 | D39: 舒城县繁华里小区2幢号楼1703室 | E39: 安徽省 | F39: 六安市 | G39: 舒城县 | H39: 安徽省六安市舒城县舒城县繁华里小区2幢号楼1703室 | I39: 变卖 | J39: 成交 | K39: 房产 | L39: 290664 | M39: 403700 | N39: 290664 | O39: 居住用房 | P39: 79.44 | Q39: 0 | S39: 单独所有 | T39: 未知 | W39: 否 | Y39: 成套住宅 | Z39: 24 | AA39: 17 | AB39: 是 | AK39: 45647.604 | AL39: https://zc-item.taobao.com/auction/842110176811.htm | AM39: =LEN(B39) -> 3 | AN39: 个人
B40: 程余 | D40: 广德市大观国际B-1406室 | E40: 安徽省 | F40: 宣城市 | G40: 广德市 | H40: 安徽省宣城市广德市大观国际B-1406室 | I40: 变卖 | J40: 成交 | K40: 房产 | L40: 230440 | M40: 411500 | N40: 230440 | O40: 商业用房 | P40: 70.48 | Q40: 0 | T40: 未知 | W40: 否 | Y40: 商业服务 | Z40: 20 | AA40: 14 | AB40: 是 | AC40: 2053-9-10 | AD40: 司法裁定 | AF40: 钢混结构 | AK40: 45596.417 | AL40: https://zc-item.taobao.com/auction/842289140957.htm | AM40: =LEN(B40) -> 2 | AN40: 个人
B41: 王成玉 | D41: 广德市桃州镇广宁路卡地亚花园23栋2单元602室房产 | E41: 安徽省 | F41: 宣城市 | G41: 广德市 | H41: 安徽省宣城市广德市桃州镇广宁路卡地亚花园23栋2单元602室 | I41: 一拍 | J41: 成交 | K41: 房产 | L41: 638671 | M41: 912386 | N41: 752671 | O41: 居住用房 | P41: 100.95 | Q41: 9.17 | T41: 未知 | W41: 未知 | Y41: 城镇住宅用地/住宅 | Z41: 0 | AA41: 6 | AB41: 是 | AC41: 2079-11-28 | AD41: 司法裁定 | AF41: 钢混结构 | AK41: 45607.435 | AL41: https://zc-item.taobao.com/auction/842293820778.htm | AM41: =LEN(B41) -> 3 | AN41: 个人
...

Sheet 抵质押物台账
A1: 抵质押物台账
A2: 序号 | B2: 资产编号 | C2: 是否终极处置 | D2: 债务人名称 | E2: 行业 | F2: 债权本金余额（万元） | G2: 债权利息余额（万元） | H2: 代垫费用余额（万元） | I2: 孳息余额（万元） | J2: 资产原值余额合计（万元） | K2: 担保形式 | L2: 保证人名称 | M2: 收购成本余额（万元） | N2: 抵（质）押物类型（一级） | O2: 抵（质）押物类型（二级） | P2: 抵（质）押物类型（三级） | Q2: 抵（质）押物处置进度 | R2: 抵（质）押人 | S2: 证件号码 | T2: 押品编号 | U2: 抵（质）押物名称 | V2: 他项权利证号/质押登记证明编号 | W2: 产权证或所有权到期日 | X2: 抵（质）押物数量 | Y2: 抵（质）押物计量单位 | Z2: 是否现场勘查 | AA2: 省、市、自治区（省级） | AB2: 市、区、州（地级） | AC2: 县、市、区（县级） | AD2: 详细位置 | AE2: 抵（质）押顺位 | AF2: 担保债权金额（万元） | AG2: 价值确认方式 | AH2: 价值评估基准日 | AI2: 抵（质）押物评估市场价值（万元） | AJ2: 瑕疵情况 | AK2: 瑕疵补充说明 | AL2: 法定优先受偿权情况 | AM2: 法定优先受偿权金额（万元） | AN2: 其他说明 | AO2: 管户经理 | AP2: 分公司 | AQ2: 所属项目 | AR2: 所属项目名称 | AS2: 投放日期 | AT2: 是否需要补录数据 | AU2: 剔除重复押品逻辑 | AV2: 考虑优先受偿和顺位剔除重复押品 | AX2: 匹配数量 不限 | AY2: 匹配数量 机构 | AZ2: 匹配数量 机构+区
A3: 316 | B3: 10240134000100000001 | C3: 否 | D3: 三胞集团有限公司 | E3: 其他未列明信息技术服务业 | F3: 197479.97 | G3: 147868.86 | H3: 17.2557 | I3: 0 | J3: 345366.09 | K3: 信用,抵押,质押,保证 | M3: 26496 | N3: 现房 | O3: 商业用房 | P3: 集中商业（购物中心，综合体商业等） | Q3: 已入库 | R3: 和县龙泉湖旅游开发有限公司 | S3: 2.4966678E8 | T3: 01012025090582043 | U3: 和县香泉镇七联小团山 | V3: 和县他项（2015）第011号 | W3: 商业2044年11月26日，综合2054年11月26日，居住2074年11月26日 | X3: 168660 | Y3: 平方米 | Z3: 是 | AA3: 安徽省 | AB3: 马鞍山市 | AC3: 和县 | AD3: 和县龙泉镇七联小团山 | AE3: 第一顺位 | AF3: 3609 | AG3: 外部评估 | AH3: 45657 | AI3: 1145 | AJ3: 否 | AL3: 不涉及 | AO3: 丁刘惠,俞恺博,史磊,吴中泽,周玲玲,尹苗 | AP3: 江苏分公司 | AQ3: 10240134 | AR3: 商业化收购中行江苏省分行对三胞集团有限公司等3户不良债权包 | AS3: 45657 | AU3: 11001 | AV3: 已剔重 | AX3: =COUNTIFS(拍卖数据!E:E,AA3,拍卖数据!F:F,AB3,拍卖数据!O:O,O3,拍卖数据!P:P,">"&X3*0.8,拍卖数据!P:P,"<"&X3*1.2) -> 0 | AY3: =COUNTIFS(拍卖数据!E:E,AA3,拍卖数据!F:F,AB3,拍卖数据!O:O,O3,拍卖数据!AN:AN,"机构",拍卖数据!P:P,">"&X3*0.8,拍卖数据!P:P,"<"&X3*1.2) -> 0 | AZ3: =COUNTIFS(拍卖数据!E:E,AA3,拍卖数据!F:F,AB3,拍卖数据!G:G,AC3,拍卖数据!O:O,O3,拍卖数据!AN:AN,"机构",拍卖数据!P:P,">"&X3*0.8,拍卖数据!P:P,"<"&X3*1.2) -> 0
A4: 317 | B4: 10240134000100000001 | C4: 否 | D4: 三胞集团有限公司 | E4: 其他未列明信息技术服务业 | F4: 197479.97 | G4: 147868.86 | H4: 17.2557 | I4: 0 | J4: 345366.09 | K4: 信用,抵押,质押,保证 | M4: 26496 | N4: 现房 | O4: 商业用房 | P4: 集中商业（购物中心，综合体商业等） | Q4: 已入库 | R4: 和县龙泉湖旅游开发有限公司 | S4: 2.4966678E8 | T4: 01012025090582042 | U4: 和县香泉镇七联小团山 | V4: 和县他项（2015）第011号 | W4: 旅游2046年5月16日，综合2056年5月16日，居住2076年5月16日 | X4: 286668 | Y4: 平方米 | Z4: 是 | AA4: 安徽省 | AB4: 马鞍山市 | AC4: 和县 | AD4: 和县龙泉镇七联小团山 | AE4: 第一顺位 | AF4: 6163 | AG4: 外部评估 | AH4: 45657 | AI4: 1145 | AJ4: 否 | AL4: 不涉及 | AO4: 丁刘惠,俞恺博,史磊,吴中泽,周玲玲,尹苗 | AP4: 江苏分公司 | AQ4: 10240134 | AR4: 商业化收购中行江苏省分行对三胞集团有限公司等3户不良债权包 | AS4: 45657 | AU4: 11001 | AV4: 已剔重 | AX4: =COUNTIFS(拍卖数据!E:E,AA4,拍卖数据!F:F,AB4,拍卖数据!O:O,O4,拍卖数据!P:P,">"&X4*0.8,拍卖数据!P:P,"<"&X4*1.2) -> 0 | AY4: =COUNTIFS(拍卖数据!E:E,AA4,拍卖数据!F:F,AB4,拍卖数据!O:O,O4,拍卖数据!AN:AN,"机构",拍卖数据!P:P,">"&X4*0.8,拍卖数据!P:P,"<"&X4*1.2) -> 0 | AZ4: =COUNTIFS(拍卖数据!E:E,AA4,拍卖数据!F:F,AB4,拍卖数据!G:G,AC4,拍卖数据!O:O,O4,拍卖数据!AN:AN,"机构",拍卖数据!P:P,">"&X4*0.8,拍卖数据!P:P,"<"&X4*1.2) -> 0
A5: 1044 | B5: 10210269000500000001 | C5: 否 | D5: 上海市兴戎石油制品有限公司 | E5: 石油及制品批发 | F5: 5996.2852 | G5: 1987.9672 | H5: 31.797802 | I5: 0 | J5: 8016.0502 | K5: 抵押,质押,保证 | M5: 52.440165 | N5: 现房 | O5: 商业用房 | P5: 集中商业（购物中心，综合体商业等） | Q5: 已入库 | R5: 安徽省金大陆房地产开发有限公司 | S5: 91340400711045010Q | T5: 01012025082720102 | U5: 安徽省淮南市田家庵区朝阳街道龙湖社区财富中心A区201室 | V5: 淮房地产他证淮田字第15008660号 | W5: 2046年5月8日 | X5: 2333.84 | Y5: 平方米 | Z5: 是 | AA5: 安徽省 | AB5: 淮南市 | AC5: 田家庵区 | AD5: 安徽省淮南市田家庵区朝阳街道龙湖社区财富中心A区201室 | AE5: 第二顺位 | AF5: 5400 | AG5: 内部测算 | AH5: 37590 | AI5: 5400 | AJ5: 否 | AL5: 不涉及 | AO5: 卢端,周若玮,宋灿可,张凯频,朱茜,李梦遥,杜旭东,杨琨(江苏分公司),王楷文,董理,谢宏娟,赵忆忆 | AP5: 江苏分公司 | AQ5: 10210269 | AR5: 商业化收购南京银行对神雾环保技术股份有限公司等8户不良资产包项目 | AS5: 44623 | AU5: 11002 | AV5: 重复内容 | AX5: =COUNTIFS(拍卖数据!E:E,AA5,拍卖数据!F:F,AB5,拍卖数据!O:O,O5,拍卖数据!P:P,">"&X5*0.8,拍卖数据!P:P,"<"&X5*1.2) -> 0 | AY5: =COUNTIFS(拍卖数据!E:E,AA5,拍卖数据!F:F,AB5,拍卖数据!O:O,O5,拍卖数据!AN:AN,"机构",拍卖数据!P:P,">"&X5*0.8,拍卖数据!P:P,"<"&X5*1.2) -> 0 | AZ5: =COUNTIFS(拍卖数据!E:E,AA5,拍卖数据!F:F,AB5,拍卖数据!G:G,AC5,拍卖数据!O:O,O5,拍卖数据!AN:AN,"机构",拍卖数据!P:P,">"&X5*0.8,拍卖数据!P:P,"<"&X5*1.2) -> 0
A6: 1054 | B6: 10210269000400000001 | C6: 否 | D6: 上海市振戎石油有限公司 | E6: 石油及制品批发 | F6: 2971.2007 | G6: 728.63018 | H6: 19.918471 | I6: 0 | J6: 3719.7494 | K6: 抵押,质押 | M6: 1685.0656 | N6: 现房 | O6: 商业用房 | P6: 集中商业（购物中心，综合体商业等） | Q6: 已入库 | R6: 安徽省金大陆房地产开发有限公司 | S6: 91340400711045010Q | T6: 01012025090581618 | U6: 安徽省淮南市田家庵区朝阳街道龙湖社区财富中心A区201室 | V6: 淮房地产他证淮田字第15004667号 | W6: 2046年5月8日 | X6: 2333.84 | Y6: 平方米 | Z6: 是 | AA6: 安徽省 | AB6: 淮南市 | AC6: 田家庵区 | AD6: 安徽省淮南市田家庵区朝阳街道龙湖社区财富中心A区201室 | AE6: 第一顺位 | AF6: 3000 | AG6: 内部测算 | AH6: 44583 | AI6: 8401.82 | AJ6: 否 | AL6: 不涉及 | AO6: 卢端,周若玮,宋灿可,张凯频,朱茜,李梦遥,杜旭东,杨琨(江苏分公司),王楷文,董理,谢宏娟,赵忆忆 | AP6: 江苏分公司 | AQ6: 10210269 | AR6: 商业化收购南京银行对神雾环保技术股份有限公司等8户不良资产包项目 | AS6: 44623 | AU6: 11001 | AV6: 已剔重 | AX6: =COUNTIFS(拍卖数据!E:E,AA6,拍卖数据!F:F,AB6,拍卖数据!O:O,O6,拍卖数据!P:P,">"&X6*0.8,拍卖数据!P:P,"<"&X6*1.2) -> 0 | AY6: =COUNTIFS(拍卖数据!E:E,AA6,拍卖数据!F:F,AB6,拍卖数据!O:O,O6,拍卖数据!AN:AN,"机构",拍卖数据!P:P,">"&X6*0.8,拍卖数据!P:P,"<"&X6*1.2) -> 0 | AZ6: =COUNTIFS(拍卖数据!E:E,AA6,拍卖数据!F:F,AB6,拍卖数据!G:G,AC6,拍卖数据!O:O,O6,拍卖数据!AN:AN,"机构",拍卖数据!P:P,">"&X6*0.8,拍卖数据!P:P,"<"&X6*1.2) -> 0
A7: 1822 | B7: 33253010010001 | C7: 否 | D7: 上海鑫泰房地产发展有限公司 | E7: 房地产业 | F7: 33560 | G7: 11864.392 | H7: 0 | J7: 45424.392 | K7: 抵押,质押,保证 | L7: 天津港天房地产投资有限公司,恒盛地产控股有限公司,恒盛天行建(天津)房地产投资有限公司,恒盛汇鑫(长春)置业有限公司,恒盛阳光鑫地(北京)置业有限公司 | M7: 9000 | N7: 现房 | O7: 商业用房 | P7: 独立商铺 | Q7: 新建 | R7: 恒盛恒茂（合肥）房地产开发有限公司 | S7: 913401006679174820 | T7: 01012025091631379 | U7: 安徽省合肥市瑶海区芜湖路2号坝上街环球中心C1R1幢商309 | V7: 皖（2021）合肥市不动产证明第11057767号 | W7: 2048/12/24 | X7: 864.82 | Y7: 平方米 | Z7: 是 | AA7: 安徽省 | AB7: 合肥市 | AC7: 瑶海区 | AD7: 芜湖路2号 | AE7: 第一顺位 | AG7: 外部评估 | AH7: 45800 | AI7: 558 | AJ7: 否 | AL7: 不涉及 | AO7: 刘瑛晖,卢涛,郑舒元 | AP7: 上海自贸区分公司 | AQ7: 33253010 | AR7: 收购爱建信托对鑫泰公司不良债权并反委托项目 | AS7: 45862 | AU7: 11001 | AV7: 已剔重 | AX7: =COUNTIFS(拍卖数据!E:E,AA7,拍卖数据!F:F,AB7,拍卖数据!O:O,O7,拍卖数据!P:P,">"&X7*0.8,拍卖数据!P:P,"<"&X7*1.2) -> 8 | AY7: =COUNTIFS(拍卖数据!E:E,AA7,拍卖数据!F:F,AB7,拍卖数据!O:O,O7,拍卖数据!AN:AN,"机构",拍卖数据!P:P,">"&X7*0.8,拍卖数据!P:P,"<"&X7*1.2) -> 3 | AZ7: =COUNTIFS(拍卖数据!E:E,AA7,拍卖数据!F:F,AB7,拍卖数据!G:G,AC7,拍卖数据!O:O,O7,拍卖数据!AN:AN,"机构",拍卖数据!P:P,">"&X7*0.8,拍卖数据!P:P,"<"&X7*1.2) -> 0
A8: 1901 | B8: 33253010010001 | C8: 否 | D8: 上海鑫泰房地产发展有限公司 | E8: 房地产业 | F8: 33560 | G8: 11864.392 | H8: 0 | J8: 45424.392 | K8: 抵押,质押,保证 | L8: 天津港天房地产投资有限公司,恒盛地产控股有限公司,恒盛天行建(天津)房地产投资有限公司,恒盛汇鑫(长春)置业有限公司,恒盛阳光鑫地(北京)置业有限公司 | M8: 9000 | N8: 现房 | O8: 商业用房 | P8: 独立商铺 | Q8: 新建 | R8: 恒盛恒茂（合肥）房地产开发有限公司 | S8: 913401006679174820 | T8: 01012025091631378 | U8: 安徽省合肥市瑶海区芜湖路2号坝上街环球中心C1R1幢商308 | V8: 皖（2021）合肥市不动产证明第11057767号 | W8: 2048/12/24 | X8: 102.12 | Y8: 平方米 | Z8: 是 | AA8: 安徽省 | AB8: 合肥市 | AC8: 瑶海区 | AD8: 芜湖路2号 | AE8: 第一顺位 | AG8: 外部评估 | AH8: 45800 | AI8: 69 | AJ8: 否 | AL8: 不涉及 | AO8: 刘瑛晖,卢涛,郑舒元 | AP8: 上海自贸区分公司 | AQ8: 33253010 | AR8: 收购爱建信托对鑫泰公司不良债权并反委托项目 | AS8: 45862 | AU8: 11001 | AV8: 已剔重 | AX8: =COUNTIFS(拍卖数据!E:E,AA8,拍卖数据!F:F,AB8,拍卖数据!O:O,O8,拍卖数据!P:P,">"&X8*0.8,拍卖数据!P:P,"<"&X8*1.2) -> 43 | AY8: =COUNTIFS(拍卖数据!E:E,AA8,拍卖数据!F:F,AB8,拍卖数据!O:O,O8,拍卖数据!AN:AN,"机构",拍卖数据!P:P,">"&X8*0.8,拍卖数据!P:P,"<"&X8*1.2) -> 4 | AZ8: =COUNTIFS(拍卖数据!E:E,AA8,拍卖数据!F:F,AB8,拍卖数据!G:G,AC8,拍卖数据!O:O,O8,拍卖数据!AN:AN,"机构",拍卖数据!P:P,">"&X8*0.8,拍卖数据!P:P,"<"&X8*1.2) -> 3
A9: 1902 | B9: 33253010010001 | C9: 否 | D9: 上海鑫泰房地产发展有限公司 | E9: 房地产业 | F9: 33560 | G9: 11864.392 | H9: 0 | J9: 45424.392 | K9: 抵押,质押,保证 | L9: 天津港天房地产投资有限公司,恒盛地产控股有限公司,恒盛天行建(天津)房地产投资有限公司,恒盛汇鑫(长春)置业有限公司,恒盛阳光鑫地(北京)置业有限公司 | M9: 9000 | N9: 现房 | O9: 商业用房 | P9: 独立商铺 | Q9: 新建 | R9: 恒盛恒茂（合肥）房地产开发有限公司 | S9: 913401006679174820 | T9: 01012025091631377 | U9: 安徽省合肥市瑶海区芜湖路2号坝上街环球中心C1R1幢商307 | V9: 皖（2021）合肥市不动产证明第11057767号 | W9: 2048/12/24 | X9: 155.27 | Y9: 平方米 | Z9: 是 | AA9: 安徽省 | AB9: 合肥市 | AC9: 瑶海区 | AD9: 芜湖路2号 | AE9: 第一顺位 | AG9: 外部评估 | AH9: 45800 | AI9: 104 | AJ9: 否 | AL9: 不涉及 | AO9: 刘瑛晖,卢涛,郑舒元 | AP9: 上海自贸区分公司 | AQ9: 33253010 | AR9: 收购爱建信托对鑫泰公司不良债权并反委托项目 | AS9: 45862 | AU9: 11001 | AV9: 已剔重 | AX9: =COUNTIFS(拍卖数据!E:E,AA9,拍卖数据!F:F,AB9,拍卖数据!O:O,O9,拍卖数据!P:P,">"&X9*0.8,拍卖数据!P:P,"<"&X9*1.2) -> 35 | AY9: =COUNTIFS(拍卖数据!E:E,AA9,拍卖数据!F:F,AB9,拍卖数据!O:O,O9,拍卖数据!AN:AN,"机构",拍卖数据!P:P,">"&X9*0.8,拍卖数据!P:P,"<"&X9*1.2) -> 4 | AZ9: =COUNTIFS(拍卖数据!E:E,AA9,拍卖数据!F:F,AB9,拍卖数据!G:G,AC9,拍卖数据!O:O,O9,拍卖数据!AN:AN,"机构",拍卖数据!P:P,">"&X9*0.8,拍卖数据!P:P,"<"&X9*1.2) -> 0
A10: 1903 | B10: 33253010010001 | C10: 否 | D10: 上海鑫泰房地产发展有限公司 | E10: 房地产业 | F10: 33560 | G10: 11864.392 | H10: 0 | J10: 45424.392 | K10: 抵押,质押,保证 | L10: 天津港天房地产投资有限公司,恒盛地产控股有限公司,恒盛天行建(天津)房地产投资有限公司,恒盛汇鑫(长春)置业有限公司,恒盛阳光鑫地(北京)置业有限公司 | M10: 9000 | N10: 现房 | O10: 商业用房 | P10: 独立商铺 | Q10: 新建 | R10: 恒盛恒茂（合肥）房地产开发有限公司 | S10: 913401006679174820 | T10: 01012025091631376 | U10: 安徽省合肥市瑶海区芜湖路2号坝上街环球中心C1R1幢商306 | V10: 皖（2021）合肥市不动产证明第11057767号 | W10: 2048/12/24 | X10: 318.96 | Y10: 平方米 | Z10: 是 | AA10: 安徽省 | AB10: 合肥市 | AC10: 瑶海区 | AD10: 芜湖路2号 | AE10: 第一顺位 | AG10: 外部评估 | AH10: 45800 | AI10: 214 | AJ10: 否 | AL10: 不涉及 | AO10: 刘瑛晖,卢涛,郑舒元 | AP10: 上海自贸区分公司 | AQ10: 33253010 | AR10: 收购爱建信托对鑫泰公司不良债权并反委托项目 | AS10: 45862 | AU10: 11001 | AV10: 已剔重 | AX10: =COUNTIFS(拍卖数据!E:E,AA10,拍卖数据!F:F,AB10,拍卖数据!O:O,O10,拍卖数据!P:P,">"&X10*0.8,拍卖数据!P:P,"<"&X10*1.2) -> 22 | AY10: =COUNTIFS(拍卖数据!E:E,AA10,拍卖数据!F:F,AB10,拍卖数据!O:O,O10,拍卖数据!AN:AN,"机构",拍卖数据!P:P,">"&X10*0.8,拍卖数据!P:P,"<"&X10*1.2) -> 4 | AZ10: =COUNTIFS(拍卖数据!E:E,AA10,拍卖数据!F:F,AB10,拍卖数据!G:G,AC10,拍卖数据!O:O,O10,拍卖数据!AN:AN,"机构",拍卖数据!P:P,">"&X10*0.8,拍卖数据!P:P,"<"&X10*1.2) -> 2
A11: 1904 | B11: 33253010010001 | C11: 否 | D11: 上海鑫泰房地产发展有限公司 | E11: 房地产业 | F11: 33560 | G11: 11864.392 | H11: 0 | J11: 45424.392 | K11: 抵押,质押,保证 | L11: 天津港天房地产投资有限公司,恒盛地产控股有限公司,恒盛天行建(天津)房地产投资有限公司,恒盛汇鑫(长春)置业有限公司,恒盛阳光鑫地(北京)置业有限公司 | M11: 9000 | N11: 现房 | O11: 商业用房 | P11: 独立商铺 | Q11: 新建 | R11: 恒盛恒茂（合肥）房地产开发有限公司 | S11: 913401006679174820 | T11: 01012025091631375 | U11: 安徽省合肥市瑶海区芜湖路2号坝上街环球中心C1R1幢商305 | V11: 皖（2021）合肥市不动产证明第11057767号 | W11: 2048/12/24 | X11: 161.03 | Y11: 平方米 | Z11: 是 | AA11: 安徽省 | AB11: 合肥市 | AC11: 瑶海区 | AD11: 芜湖路2号 | AE11: 第一顺位 | AG11: 外部评估 | AH11: 45800 | AI11: 108 | AJ11: 否 | AL11: 不涉及 | AO11: 刘瑛晖,卢涛,郑舒元 | AP11: 上海自贸区分公司 | AQ11: 33253010 | AR11: 收购爱建信托对鑫泰公司不良债权并反委托项目 | AS11: 45862 | AU11: 11001 | AV11: 已剔重 | AX11: =COUNTIFS(拍卖数据!E:E,AA11,拍卖数据!F:F,AB11,拍卖数据!O:O,O11,拍卖数据!P:P,">"&X11*0.8,拍卖数据!P:P,"<"&X11*1.2) -> 31 | AY11: =COUNTIFS(拍卖数据!E:E,AA11,拍卖数据!F:F,AB11,拍卖数据!O:O,O11,拍卖数据!AN:AN,"机构",拍卖数据!P:P,">"&X11*0.8,拍卖数据!P:P,"<"&X11*1.2) -> 2 | AZ11: =COUNTIFS(拍卖数据!E:E,AA11,拍卖数据!F:F,AB11,拍卖数据!G:G,AC11,拍卖数据!O:O,O11,拍卖数据!AN:AN,"机构",拍卖数据!P:P,">"&X11*0.8,拍卖数据!P:P,"<"&X11*1.2) -> 0
A12: 1905 | B12: 33253010010001 | C12: 否 | D12: 上海鑫泰房地产发展有限公司 | E12: 房地产业 | F12: 33560 | G12: 11864.392 | H12: 0 | J12: 45424.392 | K12: 抵押,质押,保证 | L12: 天津港天房地产投资有限公司,恒盛地产控股有限公司,恒盛天行建(天津)房地产投资有限公司,恒盛汇鑫(长春)置业有限公司,恒盛阳光鑫地(北京)置业有限公司 | M12: 9000 | N12: 现房 | O12: 商业用房 | P12: 独立商铺 | Q12: 新建 | R12: 恒盛恒茂（合肥）房地产开发有限公司 | S12: 913401006679174820 | T12: 01012025091631374 | U12: 安徽省合肥市瑶海区芜湖路2号坝上街环球中心C1R1幢商304 | V12: 皖（2021）合肥市不动产证明第11057767号 | W12: 2048/12/24 | X12: 2415.8 | Y12: 平方米 | Z12: 是 | AA12: 安徽省 | AB12: 合肥市 | AC12: 瑶海区 | AD12: 芜湖路2号 | AE12: 第一顺位 | AG12: 外部评估 | AH12: 45800 | AI12: 1429 | AJ12: 否 | AL12: 不涉及 | AO12: 刘瑛晖,卢涛,郑舒元 | AP12: 上海自贸区分公司 | AQ12: 33253010 | AR12: 收购爱建信托对鑫泰公司不良债权并反委托项目 | AS12: 45862 | AU12: 11001 | AV12: 已剔重 | AX12: =COUNTIFS(拍卖数据!E:E,AA12,拍卖数据!F:F,AB12,拍卖数据!O:O,O12,拍卖数据!P:P,">"&X12*0.8,拍卖数据!P:P,"<"&X12*1.2) -> 0 | AY12: =COUNTIFS(拍卖数据!E:E,AA12,拍卖数据!F:F,AB12,拍卖数据!O:O,O12,拍卖数据!AN:AN,"机构",拍卖数据!P:P,">"&X12*0.8,拍卖数据!P:P,"<"&X12*1.2) -> 0 | AZ12: =COUNTIFS(拍卖数据!E:E,AA12,拍卖数据!F:F,AB12,拍卖数据!G:G,AC12,拍卖数据!O:O,O12,拍卖数据!AN:AN,"机构",拍卖数据!P:P,">"&X12*0.8,拍卖数据!P:P,"<"&X12*1.2) -> 0
A13: 1906 | B13: 33253010010001 | C13: 否 | D13: 上海鑫泰房地产发展有限公司 | E13: 房地产业 | F13: 33560 | G13: 11864.392 | H13: 0 | J13: 45424.392 | K13: 抵押,质押,保证 | L13: 天津港天房地产投资有限公司,恒盛地产控股有限公司,恒盛天行建(天津)房地产投资有限公司,恒盛汇鑫(长春)置业有限公司,恒盛阳光鑫地(北京)置业有限公司 | M13: 9000 | N13: 现房 | O13: 商业用房 | P13: 独立商铺 | Q13: 新建 | R13: 恒盛恒茂（合肥）房地产开发有限公司 | S13: 913401006679174820 | T13: 01012025091631373 | U13: 安徽省合肥市瑶海区芜湖路2号坝上街环球中心C1R1幢商303 | V13: 皖（2021）合肥市不动产证明第11057767号 | W13: 2048/12/24 | X13: 1242.86 | Y13: 平方米 | Z13: 是 | AA13: 安徽省 | AB13: 合肥市 | AC13: 瑶海区 | AD13: 芜湖路2号 | AE13: 第一顺位 | AG13: 外部评估 | AH13: 45800 | AI13: 768 | AJ13: 否 | AL13: 不涉及 | AO13: 刘瑛晖,卢涛,郑舒元 | AP13: 上海自贸区分公司 | AQ13: 33253010 | AR13: 收购爱建信托对鑫泰公司不良债权并反委托项目 | AS13: 45862 | AU13: 11001 | AV13: 已剔重 | AX13: =COUNTIFS(拍卖数据!E:E,AA13,拍卖数据!F:F,AB13,拍卖数据!O:O,O13,拍卖数据!P:P,">"&X13*0.8,拍卖数据!P:P,"<"&X13*1.2) -> 5 | AY13: =COUNTIFS(拍卖数据!E:E,AA13,拍卖数据!F:F,AB13,拍卖数据!O:O,O13,拍卖数据!AN:AN,"机构",拍卖数据!P:P,">"&X13*0.8,拍卖数据!P:P,"<"&X13*1.2) -> 3 | AZ13: =COUNTIFS(拍卖数据!E:E,AA13,拍卖数据!F:F,AB13,拍卖数据!G:G,AC13,拍卖数据!O:O,O13,拍卖数据!AN:AN,"机构",拍卖数据!P:P,">"&X13*0.8,拍卖数据!P:P,"<"&X13*1.2) -> 0
A14: 1907 | B14: 33253010010001 | C14: 否 | D14: 上海鑫泰房地产发展有限公司 | E14: 房地产业 | F14: 33560 | G14: 11864.392 | H14: 0 | J14: 45424.392 | K14: 抵押,质押,保证 | L14: 天津港天房地产投资有限公司,恒盛地产控股有限公司,恒盛天行建(天津)房地产投资有限公司,恒盛汇鑫(长春)置业有限公司,恒盛阳光鑫地(北京)置业有限公司 | M14: 9000 | N14: 现房 | O14: 商业用房 | P14: 独立商铺 | Q14: 新建 | R14: 恒盛恒茂（合肥）房地产开发有限公司 | S14: 913401006679174820 | T14: 01012025091631372 | U14: 安徽省合肥市瑶海区芜湖路2号坝上街环球中心C1R1幢商302 | V14: 皖（2021）合肥市不动产证明第11057767号 | W14: 2048/12/24 | X14: 79.89 | Y14: 平方米 | Z14: 是 | AA14: 安徽省 | AB14: 合肥市 | AC14: 瑶海区 | AD14: 芜湖路2号 | AE14: 第一顺位 | AG14: 外部评估 | AH14: 45800 | AI14: 54 | AJ14: 否 | AL14: 不涉及 | AO14: 刘瑛晖,卢涛,郑舒元 | AP14: 上海自贸区分公司 | AQ14: 33253010 | AR14: 收购爱建信托对鑫泰公司不良债权并反委托项目 | AS14: 45862 | AU14: 11001 | AV14: 已剔重 | AX14: =COUNTIFS(拍卖数据!E:E,AA14,拍卖数据!F:F,AB14,拍卖数据!O:O,O14,拍卖数据!P:P,">"&X14*0.8,拍卖数据!P:P,"<"&X14*1.2) -> 80 | AY14: =COUNTIFS(拍卖数据!E:E,AA14,拍卖数据!F:F,AB14,拍卖数据!O:O,O14,拍卖数据!AN:AN,"机构",拍卖数据!P:P,">"&X14*0.8,拍卖数据!P:P,"<"&X14*1.2) -> 6 | AZ14: =COUNTIFS(拍卖数据!E:E,AA14,拍卖数据!F:F,AB14,拍卖数据!G:G,AC14,拍卖数据!O:O,O14,拍卖数据!AN:AN,"机构",拍卖数据!P:P,">"&X14*0.8,拍卖数据!P:P,"<"&X14*1.2) -> 2
A15: 1908 | B15: 33253010010001 | C15: 否 | D15: 上海鑫泰房地产发展有限公司 | E15: 房地产业 | F15: 33560 | G15: 11864.392 | H15: 0 | J15: 45424.392 | K15: 抵押,质押,保证 | L15: 天津港天房地产投资有限公司,恒盛地产控股有限公司,恒盛天行建(天津)房地产投资有限公司,恒盛汇鑫(长春)置业有限公司,恒盛阳光鑫地(北京)置业有限公司 | M15: 9000 | N15: 现房 | O15: 商业用房 | P15: 独立商铺 | Q15: 新建 | R15: 恒盛恒茂（合肥）房地产开发有限公司 | S15: 913401006679174820 | T15: 01012025091631371 | U15: 安徽省合肥市瑶海区芜湖路2号坝上街环球中心C1R1幢商301 | V15: 皖（2021）合肥市不动产证明第11057767号 | W15: 2048/12/24 | X15: 418.56 | Y15: 平方米 | Z15: 是 | AA15: 安徽省 | AB15: 合肥市 | AC15: 瑶海区 | AD15: 芜湖路2号 | AE15: 第一顺位 | AG15: 外部评估 | AH15: 45800 | AI15: 281 | AJ15: 否 | AL15: 不涉及 | AO15: 刘瑛晖,卢涛,郑舒元 | AP15: 上海自贸区分公司 | AQ15: 33253010 | AR15: 收购爱建信托对鑫泰公司不良债权并反委托项目 | AS15: 45862 | AU15: 11001 | AV15: 已剔重 | AX15: =COUNTIFS(拍卖数据!E:E,AA15,拍卖数据!F:F,AB15,拍卖数据!O:O,O15,拍卖数据!P:P,">"&X15*0.8,拍卖数据!P:P,"<"&X15*1.2) -> 4 | AY15: =COUNTIFS(拍卖数据!E:E,AA15,拍卖数据!F:F,AB15,拍卖数据!O:O,O15,拍卖数据!AN:AN,"机构",拍卖数据!P:P,">"&X15*0.8,拍卖数据!P:P,"<"&X15*1.2) -> 1 | AZ15: =COUNTIFS(拍卖数据!E:E,AA15,拍卖数据!F:F,AB15,拍卖数据!G:G,AC15,拍卖数据!O:O,O15,拍卖数据!AN:AN,"机构",拍卖数据!P:P,">"&X15*0.8,拍卖数据!P:P,"<"&X15*1.2) -> 1
A16: 1909 | B16: 33253010010001 | C16: 否 | D16: 上海鑫泰房地产发展有限公司 | E16: 房地产业 | F16: 33560 | G16: 11864.392 | H16: 0 | J16: 45424.392 | K16: 抵押,质押,保证 | L16: 天津港天房地产投资有限公司,恒盛地产控股有限公司,恒盛天行建(天津)房地产投资有限公司,恒盛汇鑫(长春)置业有限公司,恒盛阳光鑫地(北京)置业有限公司 | M16: 9000 | N16: 现房 | O16: 商业用房 | P16: 独立商铺 | Q16: 新建 | R16: 恒盛恒茂（合肥）房地产开发有限公司 | S16: 913401006679174820 | T16: 01012025091631370 | U16: 安徽省合肥市瑶海区芜湖路2号坝上街环球中心C1R1幢商219 | V16: 皖（2021）合肥市不动产证明第11057767号 | W16: 2048/12/24 | X16: 204.42 | Y16: 平方米 | Z16: 是 | AA16: 安徽省 | AB16: 合肥市 | AC16: 瑶海区 | AD16: 芜湖路2号 | AE16: 第一顺位 | AG16: 外部评估 | AH16: 45800 | AI16: 157 | AJ16: 否 | AL16: 不涉及 | AO16: 刘瑛晖,卢涛,郑舒元 | AP16: 上海自贸区分公司 | AQ16: 33253010 | AR16: 收购爱建信托对鑫泰公司不良债权并反委托项目 | AS16: 45862 | AU16: 11001 | AV16: 已剔重 | AX16: =COUNTIFS(拍卖数据!E:E,AA16,拍卖数据!F:F,AB16,拍卖数据!O:O,O16,拍卖数据!P:P,">"&X16*0.8,拍卖数据!P:P,"<"&X16*1.2) -> 22 | AY16: =COUNTIFS(拍卖数据!E:E,AA16,拍卖数据!F:F,AB16,拍卖数据!O:O,O16,拍卖数据!AN:AN,"机构",拍卖数据!P:P,">"&X16*0.8,拍卖数据!P:P,"<"&X16*1.2) -> 1 | AZ16: =COUNTIFS(拍卖数据!E:E,AA16,拍卖数据!F:F,AB16,拍卖数据!G:G,AC16,拍卖数据!O:O,O16,拍卖数据!AN:AN,"机构",拍卖数据!P:P,">"&X16*0.8,拍卖数据!P:P,"<"&X16*1.2) -> 0
A17: 1910 | B17: 33253010010001 | C17: 否 | D17: 上海鑫泰房地产发展有限公司 | E17: 房地产业 | F17: 33560 | G17: 11864.392 | H17: 0 | J17: 45424.392 | K17: 抵押,质押,保证 | L17: 天津港天房地产投资有限公司,恒盛地产控股有限公司,恒盛天行建(天津)房地产投资有限公司,恒盛汇鑫(长春)置业有限公司,恒盛阳光鑫地(北京)置业有限公司 | M17: 9000 | N17: 现房 | O17: 商业用房 | P17: 独立商铺 | Q17: 新建 | R17: 恒盛恒茂（合肥）房地产开发有限公司 | S17: 913401006679174820 | T17: 01012025091631369 | U17: 安徽省合肥市瑶海区芜湖路2号坝上街环球中心C1R1幢商218 | V17: 皖（2021）合肥市不动产证明第11057767号 | W17: 2048/12/24 | X17: 99.51 | Y17: 平方米 | Z17: 是 | AA17: 安徽省 | AB17: 合肥市 | AC17: 瑶海区 | AD17: 芜湖路2号 | AE17: 第一顺位 | AG17: 外部评估 | AH17: 45800 | AI17: 76 | AJ17: 否 | AL17: 不涉及 | AO17: 刘瑛晖,卢涛,郑舒元 | AP17: 上海自贸区分公司 | AQ17: 33253010 | AR17: 收购爱建信托对鑫泰公司不良债权并反委托项目 | AS17: 45862 | AU17: 11001 | AV17: 已剔重 | AX17: =COUNTIFS(拍卖数据!E:E,AA17,拍卖数据!F:F,AB17,拍卖数据!O:O,O17,拍卖数据!P:P,">"&X17*0.8,拍卖数据!P:P,"<"&X17*1.2) -> 47 | AY17: =COUNTIFS(拍卖数据!E:E,AA17,拍卖数据!F:F,AB17,拍卖数据!O:O,O17,拍卖数据!AN:AN,"机构",拍卖数据!P:P,">"&X17*0.8,拍卖数据!P:P,"<"&X17*1.2) -> 4 | AZ17: =COUNTIFS(拍卖数据!E:E,AA17,拍卖数据!F:F,AB17,拍卖数据!G:G,AC17,拍卖数据!O:O,O17,拍卖数据!AN:AN,"机构",拍卖数据!P:P,">"&X17*0.8,拍卖数据!P:P,"<"&X17*1.2) -> 3
A18: 1911 | B18: 33253010010001 | C18: 否 | D18: 上海鑫泰房地产发展有限公司 | E18: 房地产业 | F18: 33560 | G18: 11864.392 | H18: 0 | J18: 45424.392 | K18: 抵押,质押,保证 | L18: 天津港天房地产投资有限公司,恒盛地产控股有限公司,恒盛天行建(天津)房地产投资有限公司,恒盛汇鑫(长春)置业有限公司,恒盛阳光鑫地(北京)置业有限公司 | M18: 9000 | N18: 现房 | O18: 商业用房 | P18: 独立商铺 | Q18: 新建 | R18: 恒盛恒茂（合肥）房地产开发有限公司 | S18: 913401006679174820 | T18: 01012025091631368 | U18: 安徽省合肥市瑶海区芜湖路2号坝上街环球中心C1R1幢商217 | V18: 皖（2021）合肥市不动产证明第11057767号 | W18: 2048/12/24 | X18: 139.51 | Y18: 平方米 | Z18: 是 | AA18: 安徽省 | AB18: 合肥市 | AC18: 瑶海区 | AD18: 芜湖路2号 | AE18: 第一顺位 | AG18: 外部评估 | AH18: 45800 | AI18: 107 | AJ18: 否 | AL18: 不涉及 | AO18: 刘瑛晖,卢涛,郑舒元 | AP18: 上海自贸区分公司 | AQ18: 33253010 | AR18: 收购爱建信托对鑫泰公司不良债权并反委托项目 | AS18: 45862 | AU18: 11001 | AV18: 已剔重 | AX18: =COUNTIFS(拍卖数据!E:E,AA18,拍卖数据!F:F,AB18,拍卖数据!O:O,O18,拍卖数据!P:P,">"&X18*0.8,拍卖数据!P:P,"<"&X18*1.2) -> 33 | AY18: =COUNTIFS(拍卖数据!E:E,AA18,拍卖数据!F:F,AB18,拍卖数据!O:O,O18,拍卖数据!AN:AN,"机构",拍卖数据!P:P,">"&X18*0.8,拍卖数据!P:P,"<"&X18*1.2) -> 5 | AZ18: =COUNTIFS(拍卖数据!E:E,AA18,拍卖数据!F:F,AB18,拍卖数据!G:G,AC18,拍卖数据!O:O,O18,拍卖数据!AN:AN,"机构",拍卖数据!P:P,">"&X18*0.8,拍卖数据!P:P,"<"&X18*1.2) -> 0
... A78: 1973 | B78: 33253010010001 | C78: 否 | D78: 上海鑫泰房地产发展有限公司 | E78: 房地产业 | F78: 33560 | G78: 11864.392 | H78: 0 | J78: 45424.392 | K78: 抵押,质押,保证 | L78: 天津港天房地产投资有限公司,恒盛地产控股有限公司,恒盛天行建(天津)房地产投资有限公司,恒盛汇鑫(长春)置业有限公司,恒盛阳光鑫地(北京)置业有限公司 | M78: 9000 | N78: 现房 | O78: 商业用房 | P78: 独立商铺 | Q78: 新建 | R78: 恒盛恒茂（合肥）房地产开发有限公司 | S78: 913401006679174820 | T78: 01012025091631380 | U78: 安徽省合肥市瑶海区芜湖路2号坝上街环球中心C1R1幢商401 | V78: 皖（2021）合肥市不动产证明第11057767号 | W78: 2048/12/24 | X78: 362.78 | Y78: 平方米 | Z78: 是 | AA78: 安徽省 | AB78: 合肥市 | AC78: 瑶海区 | AD78: 芜湖路2号 | AE78: 第一顺位 | AG78: 外部评估 | AH78: 45800 | AI78: 209 | AJ78: 否 | AL78: 不涉及 | AO78: 刘瑛晖,卢涛,郑舒元 | AP78: 上海自贸区分公司 | AQ78: 33253010 | AR78: 收购爱建信托对鑫泰公司不良债权并反委托项目 | AS78: 45862 | AU78: 11001 | AV78: 已剔重 | AX78: =COUNTIFS(拍卖数据!E:E,AA78,拍卖数据!F:F,AB78,拍卖数据!O:O,O78,拍卖数据!P:P,">"&X78*0.8,拍卖数据!P:P,"<"&X78*1.2) -> 8 | AY78: =COUNTIFS(拍卖数据!E:E,AA78,拍卖数据!F:F,AB78,拍卖数据!O:O,O78,拍卖数据!AN:AN,"机构",拍卖数据!P:P,">"&X78*0.8,拍卖数据!P:P,"<"&X78*1.2) -> 2 | AZ78: =COUNTIFS(拍卖数据!E:E,AA78,拍卖数据!F:F,AB78,拍卖数据!G:G,AC78,拍卖数据!O:O,O78,拍卖数据!AN:AN,"机构",拍卖数据!P:P,">"&X78*0.8,拍卖数据!P:P,"<"&X78*1.2) -> 2
A79: 2094 | B79: 09180125000700000001 | C79: 否 | D79: 上海龙德资源股份有限公司 | E79: 金属及金属矿批发 | F79: 6317.6904 | G79: 1512.301 | H79: 0 | I79: 0 | J79: 7829.9914 | K79: 抵押,保证 | L79: 广东振戎能源有限公司 | M79: 2574.1348 | N79: 现房 | O79: 商业用房 | P79: 集中商业（购物中心，综合体商业等） | Q79: 新建 | R79: 安徽省金大陆房地产开发有限公司 | S79: 91340400711045010Q | T79: 01012025081220008 | U79: 安徽省淮南市田家庵区朝阳街道龙湖社区财富中心B区101室的商业地产 | V79: 淮房地产他证淮田字第1421618号 | W79: 2046/5/8 | X79: 2745.22 | Y79: 平方米 | Z79: 是 | AA79: 安徽省 | AB79: 淮南市 | AC79: 田家庵区 | AD79: 田家庵区朝阳街道龙湖社区财富中心B区101室 | AE79: 第一顺位 | AF79: 10000 | AG79: 内部测算 | AH79: 43415 | AI79: 6902.5502 | AJ79: 是 | AK79: A01.押品非首位查封 | AL79: 不涉及 | AO79: 吴薇(上海分公司),张咏梅,徐工婷,杨晓峰,沈家伦,王军(上海分公司),蔡薇,邓秋韵,郦亨利 | AP79: 上海分公司 | AQ79: 09180125 | AR79: 商业化收购中信银行上海分行对上海常信实业有限公司等17户不良资产项目 | AS79: 43440 | AU79: 11001 | AV79: 已剔重 | AX79: =COUNTIFS(拍卖数据!E:E,AA79,拍卖数据!F:F,AB79,拍卖数据!O:O,O79,拍卖数据!P:P,">"&X79*0.8,拍卖数据!P:P,"<"&X79*1.2) -> 0 | AY79: =COUNTIFS(拍卖数据!E:E,AA79,拍卖数据!F:F,AB79,拍卖数据!O:O,O79,拍卖数据!AN:AN,"机构",拍卖数据!P:P,">"&X79*0.8,拍卖数据!P:P,"<"&X79*1.2) -> 0 | AZ79: =COUNTIFS(拍卖数据!E:E,AA79,拍卖数据!F:F,AB79,拍卖数据!G:G,AC79,拍卖数据!O:O,O79,拍卖数据!AN:AN,"机构",拍卖数据!P:P,">"&X79*0.8,拍卖数据!P:P,"<"&X79*1.2) -> 0
A80: 4161 | B80: 12190065002100000001 | C80: 否 | D80: 中建永顺集团有限公司 | E80: 园林绿化工程施工 | F80: 630 | G80: 108.96453 | H80: 0 | I80: 0 | J80: 738.96453 | K80: 抵押,质押,保证 | M80: 410.22393 | N80: 现房 | O80: 商业用房 | P80: 集中商业（购物中心，综合体商业等） | Q80: 新建 | R80: 中建永顺集团有限公司 | S80: 913411036849594573 | T80: 01012025081220436 | U80: 定远县定城镇东城南路绿园小区30幢1-5至1-12 室皖（2016）定远县不动产权第0004884号 | V80: 皖（2016）定远县不动产证明第0008753号 | W80: 2047/1/1 | X80: 1109.34 | Y80: 平方米 | Z80: 是 | AA80: 安徽省 | AB80: 滁州市 | AC80: 定远县 | AD80: 定远县定城镇东城南路绿园小区30幢1-5至1-12 室 | AE80: 第一顺位 | AF80: 3671.02 | AG80: 外部评估 | AH80: 43689 | AI80: 1211.95 | AJ80: 否 | AL80: 不涉及 | AO80: 刘伟(安徽分公司),姜碧霏,张乐群,张梅,戴宁,牛琪,许之玮,赵艳(安徽分公司),郑蓓,陈文轩,齐奥 | AP80: 安徽分公司 | AQ80: 12190065 | AR80: 收购安徽工行对安徽豪森纸业等29户企业持有的金融不良债权项目 | AS80: 43795 | AU80: 11001 | AV80: 已剔重 | AX80: =COUNTIFS(拍卖数据!E:E,AA80,拍卖数据!F:F,AB80,拍卖数据!O:O,O80,拍卖数据!P:P,">"&X80*0.8,拍卖数据!P:P,"<"&X80*1.2) -> 0 | AY80: =COUNTIFS(拍卖数据!E:E,AA80,拍卖数据!F:F,AB80,拍卖数据!O:O,O80,拍卖数据!AN:AN,"机构",拍卖数据!P:P,">"&X80*0.8,拍卖数据!P:P,"<"&X80*1.2) -> 0 | AZ80: =COUNTIFS(拍卖数据!E:E,AA80,拍卖数据!F:F,AB80,拍卖数据!G:G,AC80,拍卖数据!O:O,O80,拍卖数据!AN:AN,"机构",拍卖数据!P:P,">"&X80*0.8,拍卖数据!P:P,"<"&X80*1.2) -> 0
A81: 4162 | B81: 12190065002100000001 | C81: 否 | D81: 中建永顺集团有限公司 | E81: 园林绿化工程施工 | F81: 630 | G81: 108.96453 | H81: 0 | I81: 0 | J81: 738.96453 | K81: 抵押,质押,保证 | M81: 410.22393 | N81: 现房 | O81: 商业用房 | P81: 集中商业（购物中心，综合体商业等） | Q81: 新建 | R81: 中建永顺集团有限公司 | S81: 913411036849594573 | T81: 01012025081220439 | U81: 定远县定城镇东城南路绿园小区30幢2-13室皖（2016）定远县不动产权第0004893号 | V81: 皖（2016）定远县不动产证明第0008749号 | W81: 2047/1/1 | X81: 19.69 | Y81: 平方米 | Z81: 是 | AA81: 安徽省 | AB81: 滁州市 | AC81: 定远县 | AD81: 定远县定城镇东城南路绿园小区30幢2-13室 | AE81: 第一顺位 | AF81: 3671.02 | AG81: 外部评估 | AH81: 43689 | AI81: 11.32 | AJ81: 否 | AL81: 不涉及 | AO81: 刘伟(安徽分公司),姜碧霏,张乐群,张梅,戴宁,牛琪,许之玮,赵艳(安徽分公司),郑蓓,陈文轩,齐奥 | AP81: 安徽分公司 | AQ81: 12190065 | AR81: 收购安徽工行对安徽豪森纸业等29户企业持有的金融不良债权项目 | AS81: 43795 | AU81: 11001 | AV81: 已剔重 | AX81: =COUNTIFS(拍卖数据!E:E,AA81,拍卖数据!F:F,AB81,拍卖数据!O:O,O81,拍卖数据!P:P,">"&X81*0.8,拍卖数据!P:P,"<"&X81*1.2) -> 1 | AY81: =COUNTIFS(拍卖数据!E:E,AA81,拍卖数据!F:F,AB81,拍卖数据!O:O,O81,拍卖数据!AN:AN,"机构",拍卖数据!P:P,">"&X81*0.8,拍卖数据!P:P,"<"&X81*1.2) -> 0 | AZ81: =COUNTIFS(拍卖数据!E:E,AA81,拍卖数据!F:F,AB81,拍卖数据!G:G,AC81,拍卖数据!O:O,O81,拍卖数据!AN:AN,"机构",拍卖数据!P:P,">"&X81*0.8,拍卖数据!P:P,"<"&X81*1.2) -> 0
A82: 4163 | B82: 12190065002100000002 | C82: 否 | D82: 中建永顺集团有限公司 | E82: 园林绿化工程施工 | F82: 627 | G82: 107.44316 | H82: 0 | I82: 0 | J82: 734.44316 | K82: 抵押,质押,保证 | M82: 408.27048 | N82: 现房 | O82: 商业用房 | P82: 集中商业（购物中心，综合体商业等） | Q82: 新建 | R82: 中建永顺集团有限公司 | S82: 913411036849594573 | T82: 01012025081220437 | U82: 定远县定城镇东城南路绿园小区30幢1-4 室皖（2016）定远县不动产权第0004891号 | V82: 皖（2016）定远县不动产证明第0008748号 | W82: 2047/1/1 | X82: 57.47 | Y82: 平方米 | Z82: 是 | AA82: 安徽省 | AB82: 滁州市 | AC82: 定远县 | AD82: 定远县定城镇东城南路绿园小区30幢1-4 室 | AE82: 第一顺位 | AF82: 3671.02 | AG82: 外部评估 | AH82: 43689 | AI82: 66.09 | AJ82: 否 | AL82: 不涉及 | AO82: 刘伟(安徽分公司),姜碧霏,张乐群,张梅,戴宁,牛琪,许之玮,赵艳(安徽分公司),郑蓓,陈文轩,齐奥 | AP82: 安徽分公司 | AQ82: 12190065 | AR82: 收购安徽工行对安徽豪森纸业等29户企业持有的金融不良债权项目 | AS82: 43795 | AU82: 11001 | AV82: 已剔重 | AX82: =COUNTIFS(拍卖数据!E:E,AA82,拍卖数据!F:F,AB82,拍卖数据!O:O,O82,拍卖数据!P:P,">"&X82*0.8,拍卖数据!P:P,"<"&X82*1.2) -> 31 | AY82: =COUNTIFS(拍卖数据!E:E,AA82,拍卖数据!F:F,AB82,拍卖数据!O:O,O82,拍卖数据!AN:AN,"机构",拍卖数据!P:P,">"&X82*0.8,拍卖数据!P:P,"<"&X82*1.2) -> 0 | AZ82: =COUNTIFS(拍卖数据!E:E,AA82,拍卖数据!F:F,AB82,拍卖数据!G:G,AC82,拍卖数据!O:O,O82,拍卖数据!AN:AN,"机构",拍卖数据!P:P,">"&X82*0.8,拍卖数据!P:P,"<"&X82*1.2) -> 0
A83: 4164 | B83: 12190065002100000002 | C83: 否 | D83: 中建永顺集团有限公司 | E83: 园林绿化工程施工 | F83: 627 | G83: 107.44316 | H83: 0 | I83: 0 | J83: 734.44316 | K83: 抵押,质押,保证 | M83: 408.27048 | N83: 现房 | O83: 商业用房 | P83: 集中商业（购物中心，综合体商业等） | Q83: 新建 | R83: 中建永顺集团有限公司 | S83: 913411036849594573 | T83: 01012025081220440 | U83: 定远县定城镇东城南路绿园小区33幢北10室皖（2016）定远县不动产权第0004890号 | V83: 皖（2016）定远县不动产证明第0008750号 | W83: 2047/1/1 | X83: 115.58 | Y83: 平方米 | Z83: 是 | AA83: 安徽省 | AB83: 滁州市 | AC83: 定远县 | AD83: 定远县定城镇东城南路绿园小区33幢北10室 | AE83: 第一顺位 | AF83: 3671.02 | AG83: 外部评估 | AH83: 43689 | AI83: 121.36 | AJ83: 否 | AL83: 不涉及 | AO83: 刘伟(安徽分公司),姜碧霏,张乐群,张梅,戴宁,牛琪,许之玮,赵艳(安徽分公司),郑蓓,陈文轩,齐奥 | AP83: 安徽分公司 | AQ83: 12190065 | AR83: 收购安徽工行对安徽豪森纸业等29户企业持有的金融不良债权项目 | AS83: 43795 | AU83: 11001 | AV83: 已剔重 | AX83: =COUNTIFS(拍卖数据!E:E,AA83,拍卖数据!F:F,AB83,拍卖数据!O:O,O83,拍卖数据!P:P,">"&X83*0.8,拍卖数据!P:P,"<"&X83*1.2) -> 48 | AY83: =COUNTIFS(拍卖数据!E:E,AA83,拍卖数据!F:F,AB83,拍卖数据!O:O,O83,拍卖数据!AN:AN,"机构",拍卖数据!P:P,">"&X83*0.8,拍卖数据!P:P,"<"&X83*1.2) -> 0 | AZ83: =COUNTIFS(拍卖数据!E:E,AA83,拍卖数据!F:F,AB83,拍卖数据!G:G,AC83,拍卖数据!O:O,O83,拍卖数据!AN:AN,"机构",拍卖数据!P:P,">"&X83*0.8,拍卖数据!P:P,"<"&X83*1.2) -> 0
A84: 4165 | B84: 12190065002100000003 | C84: 否 | D84: 中建永顺集团有限公司 | E84: 园林绿化工程施工 | F84: 440 | G84: 72.246319 | H84: 0 | I84: 0 | J84: 512.24632 | K84: 抵押,质押,保证 | M84: 286.5056 | N84: 现房 | O84: 商业用房 | P84: 集中商业（购物中心，综合体商业等） | Q84: 新建 | R84: 中建永顺集团有限公司 | S84: 913411036849594573 | T84: 01012025081220438 | U84: 定远县定城镇东城南路绿园小区30幢2-1、2-4室皖（2016）定远县不动产权第0004892号 | V84: 皖（2016）定远县不动产证明第0008747号 | W84: 2047/1/1 | X84: 157.06 | Y84: 平方米 | Z84: 是 | AA84: 安徽省 | AB84: 滁州市 | AC84: 定远县 | AD84: 定远县定城镇东城南路绿园小区30幢2-1、2-4室 | AE84: 第一顺位 | AF84: 3671.02 | AG84: 外部评估 | AH84: 43689 | AI84: 90.31 | AJ84: 否 | AL84: 不涉及 | AO84: 刘伟(安徽分公司),姜碧霏,张乐群,张梅,戴宁,牛琪,许之玮,赵艳(安徽分公司),郑蓓,陈文轩,齐奥 | AP84: 安徽分公司 | AQ84: 12190065 | AR84: 收购安徽工行对安徽豪森纸业等29户企业持有的金融不良债权项目 | AS84: 43795 | AU84: 11001 | AV84: 已剔重 | AX84: =COUNTIFS(拍卖数据!E:E,AA84,拍卖数据!F:F,AB84,拍卖数据!O:O,O84,拍卖数据!P:P,">"&X84*0.8,拍卖数据!P:P,"<"&X84*1.2) -> 42 | AY84: =COUNTIFS(拍卖数据!E:E,AA84,拍卖数据!F:F,AB84,拍卖数据!O:O,O84,拍卖数据!AN:AN,"机构",拍卖数据!P:P,">"&X84*0.8,拍卖数据!P:P,"<"&X84*1.2) -> 0 | AZ84: =COUNTIFS(拍卖数据!E:E,AA84,拍卖数据!F:F,AB84,拍卖数据!G:G,AC84,拍卖数据!O:O,O84,拍卖数据!AN:AN,"机构",拍卖数据!P:P,">"&X84*0.8,拍卖数据!P:P,"<"&X84*1.2) -> 0
A85: 4166 | B85: 12190065002100000003 | C85: 否 | D85: 中建永顺集团有限公司 | E85: 园林绿化工程施工 | F85: 440 | G85: 72.246319 | H85: 0 | I85: 0 | J85: 512.24632 | K85: 抵押,质押,保证 | M85: 286.5056 | N85: 现房 | O85: 商业用房 | P85: 集中商业（购物中心，综合体商业等） | Q85: 新建 | R85: 中建永顺集团有限公司 | S85: 913411036849594573 | T85: 01012025081220442 | U85: 定远县定城镇东城南路绿园小区33幢北13室皖（2016）定远县不动产权第0004887号 | V85: 皖（2016）定远县不动产证明第0008752号 | W85: 2047/1/1 | X85: 1325.99 | Y85: 平方米 | Z85: 是 | AA85: 安徽省 | AB85: 滁州市 | AC85: 定远县 | AD85: 定远县定城镇东城南路绿园小区33幢北13室 | AE85: 第一顺位 | AF85: 3671.02 | AG85: 外部评估 | AH85: 43689 | AI85: 991.84 | AJ85: 否 | AL85: 不涉及 | AO85: 刘伟(安徽分公司),姜碧霏,张乐群,张梅,戴宁,牛琪,许之玮,赵艳(安徽分公司),郑蓓,陈文轩,齐奥 | AP85: 安徽分公司 | AQ85: 12190065 | AR85: 收购安徽工行对安徽豪森纸业等29户企业持有的金融不良债权项目 | AS85: 43795 | AU85: 11001 | AV85: 已剔重 | AX85: =COUNTIFS(拍卖数据!E:E,AA85,拍卖数据!F:F,AB85,拍卖数据!O:O,O85,拍卖数据!P:P,">"&X85*0.8,拍卖数据!P:P,"<"&X85*1.2) -> 1 | AY85: =COUNTIFS(拍卖数据!E:E,AA85,拍卖数据!F:F,AB85,拍卖数据!O:O,O85,拍卖数据!AN:AN,"机构",拍卖数据!P:P,">"&X85*0.8,拍卖数据!P:P,"<"&X85*1.2) -> 0 | AZ85: =COUNTIFS(拍卖数据!E:E,AA85,拍卖数据!F:F,AB85,拍卖数据!G:G,AC85,拍卖数据!O:O,O85,拍卖数据!AN:AN,"机构",拍卖数据!P:P,">"&X85*0.8,拍卖数据!P:P,"<"&X85*1.2) -> 0
A86: 4167 | B86: 12190065002100000003 | C86: 否 | D86: 中建永顺集团有限公司 | E86: 园林绿化工程施工 | F86: 440 | G86: 72.246319 | H86: 0 | I86: 0 | J86: 512.24632 | K86: 抵押,质押,保证 | M86: 286.5056 | N86: 现房 | O86: 商业用房 | P86: 集中商业（购物中心，综合体商业等） | Q86: 新建 | R86: 中建永顺集团有限公司 | S86: 913411036849594573 | T86: 01012025081220441 | U86: 定远县定城镇东城南路绿园小区33幢北7室皖（2016）定远县不动产权第0004889号 | V86: 皖（2016）定远县不动产证明第0008751号 | W86: 2047/1/1 | X86: 92.98 | Y86: 平方米 | Z86: 是 | AA86: 安徽省 | AB86: 滁州市 | AC86: 定远县 | AD86: 定远县定城镇东城南路绿园小区33幢北7室 | AE86: 第一顺位 | AF86: 3671.02 | AG86: 外部评估 | AH86: 43689 | AI86: 73.22 | AJ86: 否 | AL86: 不涉及 | AO86: 刘伟(安徽分公司),姜碧霏,张乐群,张梅,戴宁,牛琪,许之玮,赵艳(安徽分公司),郑蓓,陈文轩,齐奥 | AP86: 安徽分公司 | AQ86: 12190065 | AR86: 收购安徽工行对安徽豪森纸业等29户企业持有的金融不良债权项目 | AS86: 43795 | AU86: 11001 | AV86: 已剔重 | AX86: =COUNTIFS(拍卖数据!E:E,AA86,拍卖数据!F:F,AB86,拍卖数据!O:O,O86,拍卖数据!P:P,">"&X86*0.8,拍卖数据!P:P,"<"&X86*1.2) -> 35 | AY86: =COUNTIFS(拍卖数据!E:E,AA86,拍卖数据!F:F,AB86,拍卖数据!O:O,O86,拍卖数据!AN:AN,"机构",拍卖数据!P:P,">"&X86*0.8,拍卖数据!P:P,"<"&X86*1.2) -> 0 | AZ86: =COUNTIFS(拍卖数据!E:E,AA86,拍卖数据!F:F,AB86,拍卖数据!G:G,AC86,拍卖数据!O:O,O86,拍卖数据!AN:AN,"机构",拍卖数据!P:P,">"&X86*0.8,拍卖数据!P:P,"<"&X86*1.2) -> 0
A87: 4479 | B87: 19190128000100000001 | C87: 否 | D87: 中福天工建设集团有限公司 | E87: 住宅房屋建筑 | F87: 57425.297 | G87: 0 | H87: 0 | I87: 0 | J87: 57425.297 | K87: 信用 | M87: 56484.997 | N87: 在建工程 | O87: 商业用房在建工程 | P87: 商业用房在建工程 | Q87: 已入库 | R87: 安徽安粮金属市场投资有限公司 | S87: 91340122684984388T | T87: 01032025090699359 | U87: 位于合肥市华商国际名优特产交易中心项目的873套面积合计32,027.92平方米的商铺在建工程 | V87: 皖（2020）肥东县不动产证明第0000126号 | W87: Sat Jul 15 00:00:00 CST 2051 | X87: 32027.92 | Y87: 平方米 | Z87: 是 | AA87: 安徽省 | AB87: 合肥市 | AC87: 肥东县 | AD87: 撮镇镇裕溪路南 | AE87: 第一顺位 | AF87: 29636.21 | AG87: 外部评估 | AH87: 44111 | AI87: 29636.21 | AJ87: 否 | AL87: 涉及 | AM87: 30837576 | AN87: 根据破产管理人报告，截至2022年10月31日，管理人审查认定特定财产担保类14599634.4元，职工债权5570319.65元，税款债权10667622.04元。 | AO87: 李裕泽,梁洁容,莫志闻 | AP87: 广东分公司 | AQ87: 19190128 | AR87: 收购处置中核伟业对中核工建设集团持有的不良债权项目 | AS87: 43825 | AU87: 10001 | AV87: 已剔重 | AX87: =COUNTIFS(拍卖数据!E:E,AA87,拍卖数据!F:F,AB87,拍卖数据!O:O,O87,拍卖数据!P:P,">"&X87*0.8,拍卖数据!P:P,"<"&X87*1.2) -> 0 | AY87: =COUNTIFS(拍卖数据!E:E,AA87,拍卖数据!F:F,AB87,拍卖数据!O:O,O87,拍卖数据!AN:AN,"机构",拍卖数据!P:P,">"&X87*0.8,拍卖数据!P:P,"<"&X87*1.2) -> 0 | AZ87: =COUNTIFS(拍卖数据!E:E,AA87,拍卖数据!F:F,AB87,拍卖数据!G:G,AC87,拍卖数据!O:O,O87,拍卖数据!AN:AN,"机构",拍卖数据!P:P,">"&X87*0.8,拍卖数据!P:P,"<"&X87*1.2) -> 0
A88: 4480 | B88: 19190128000100000001 | C88: 否 | D88: 中福天工建设集团有限公司 | E88: 住宅房屋建筑 | F88: 57425.297 | G88: 0 | H88: 0 | I88: 0 | J88: 57425.297 | K88: 信用 | M88: 56484.997 | N88: 在建工程 | O88: 商业用房在建工程 | P88: 商业用房在建工程 | Q88: 已入库 | R88: 安徽安粮金属市场投资有限公司 | S88: 91340122684984388T | T88: 01032025090699360 | U88: 位于合肥市华商国际名优特产交易中心项目的873套面积合计32,027.92平方米的商铺在建工程 | V88: 皖（2020）肥东县不动产证明第0000126号 | W88: Sat Jul 15 00:00:00 CST 2051 | X88: 32027.92 | Y88: 平方米 | Z88: 是 | AA88: 安徽省 | AB88: 合肥市 | AC88: 肥东县 | AD88: 撮镇镇裕溪路南 | AE88: 第一顺位 | AF88: 29636.21 | AG88: 外部评估 | AH88: 44111 | AI88: 29636.21 | AJ88: 否 | AL88: 涉及 | AM88: 30837576 | AN88: 根据破产管理人报告，截至2022年10月31日，管理人审查认定特定财产担保类14599634.4元，职工债权5570319.65元，税款债权10667622.04元。 | AO88: 李裕泽,梁洁容,莫志闻 | AP88: 广东分公司 | AQ88: 19190128 | AR88: 收购处置中核伟业对中核工建设集团持有的不良债权项目 | AS88: 43825 | AU88: 10001 | AV88: 重复内容 | AX88: =COUNTIFS(拍卖数据!E:E,AA88,拍卖数据!F:F,AB88,拍卖数据!O:O,O88,拍卖数据!P:P,">"&X88*0.8,拍卖数据!P:P,"<"&X88*1.2) -> 0 | AY88: =COUNTIFS(拍卖数据!E:E,AA88,拍卖数据!F:F,AB88,拍卖数据!O:O,O88,拍卖数据!AN:AN,"机构",拍卖数据!P:P,">"&X88*0.8,拍卖数据!P:P,"<"&X88*1.2) -> 0 | AZ88: =COUNTIFS(拍卖数据!E:E,AA88,拍卖数据!F:F,AB88,拍卖数据!G:G,AC88,拍卖数据!O:O,O88,拍卖数据!AN:AN,"机构",拍卖数据!P:P,">"&X88*0.8,拍卖数据!P:P,"<"&X88*1.2) -> 0
A89: 4780 | B89: 12240029000200000001 | C89: 否 | D89: 中豪建设股份有限公司 | E89: 房屋建筑业 | F89: 1000 | G89: 51.884012 | H89: 4.5 | I89: 0 | J89: 1056.384 | K89: 抵押,质押,保证 | L89: 安徽顺风(集团)房地产开发有限公司,王学成,袁智荣 | M89: 369 | N89: 现房 | O89: 商业用房 | P89: 集中商业（购物中心，综合体商业等） | Q89: 新建 | R89: 安徽顺风（集团）房地产开发有限公司 | S89: 91341102152627611G | T89: 01012025081220645 | U89: 滁州市南谯北路615号（顺风大厦）综合楼（商服）二层房地权滁字第2008007683号 | V89: 皖（2019）滁州市不动产证明第0036482号 | W89: 51399 | X89: 1644.39 | Y89: 平方米 | Z89: 是 | AA89: 安徽省 | AB89: 滁州市 | AC89: 南谯区 | AD89: 滁州市南谯北路615号（顺风大厦）综合楼（商服）二层 | AE89: 第一顺位 | AF89: 2660 | AG89: 外部评估 | AH89: 45443 | AI89: 1372.57 | AJ89: 否 | AL89: 不涉及 | AO89: 张梅,赵艳(安徽分公司),陈文轩,齐奥 | AP89: 安徽分公司 | AQ89: 12240029 | AR89: 收购安徽建行2024年第二季度4户不良资产包项目 | AS89: 45469 | AU89: 11001 | AV89: 已剔重 | AX89: =COUNTIFS(拍卖数据!E:E,AA89,拍卖数据!F:F,AB89,拍卖数据!O:O,O89,拍卖数据!P:P,">"&X89*0.8,拍卖数据!P:P,"<"&X89*1.2) -> 2 | AY89: =COUNTIFS(拍卖数据!E:E,AA89,拍卖数据!F:F,AB89,拍卖数据!O:O,O89,拍卖数据!AN:AN,"机构",拍卖数据!P:P,">"&X89*0.8,拍卖数据!P:P,"<"&X89*1.2) -> 1 | AZ89: =COUNTIFS(拍卖数据!E:E,AA89,拍卖数据!F:F,AB89,拍卖数据!G:G,AC89,拍卖数据!O:O,O89,拍卖数据!AN:AN,"机构",拍卖数据!P:P,">"&X89*0.8,拍卖数据!P:P,"<"&X89*1.2) -> 0
A90: 5243 | B90: 12240053003900000001 | C90: 否 | D90: 临泉县金城国际实业有限公司 | E90: 其他未列明零售业 | F90: 500 | G90: 158.65507 | H90: 0.5 | I90: 0 | J90: 659.15507 | K90: 抵押,质押,保证 | L90: 代旭,戴驰 | M90: 0 | N90: 在建工程 | O90: 商业用房在建工程 | P90: 商业用房在建工程 | Q90: 新建 | R90: 临泉县金城国际实业有限公司 | S90: 91341221MA2MX1K358 | T90: 01032025091430001 | U90: 临泉县光明路与前进路交叉口西北侧金城大厦501、516、517、518、521A、522、538A、539、544、601、617、619、638A、643、701、717、721A、738A、1201、1701、2403、2501、2504、2604室（在建工程）皖（2021）临泉县不动产证明第0012619号 | V90: 皖（2021）临泉县不动产证明第0012619号 | W90: 2056/1/1 | X90: 1418.66 | Y90: 平方米 | Z90: 是 | AA90: 安徽省 | AB90: 阜阳市 | AC90: 临泉县 | AD90: 临泉县光明路与前进路交叉口西北侧金城大厦501、516、517、518、521A、522、538A、539、544、601、617、619、638A、643、701、717、721A、738A、1201、1701、2403、2501、2504、2604室（在建工程） | AE90: 第一顺位 | AF90: 500 | AG90: 外部评估 | AH90: 44355 | AI90: 1217.1 | AJ90: 是 | AK90: A03.押品被私售、抵债、转移或占用，难以追讨或清退 | AL90: 不涉及 | AO90: 张乐群,曹吉峰,董俣顺,许之玮,邹熠峰,郑舒凌 | AP90: 安徽分公司 | AQ90: 12240053 | AR90: 收购颍东农商行2024年第1批12户不良资产包项目 | AS90: 45587 | AU90: 11001 | AV90: 已剔重 | AX90: =COUNTIFS(拍卖数据!E:E,AA90,拍卖数据!F:F,AB90,拍卖数据!O:O,O90,拍卖数据!P:P,">"&X90*0.8,拍卖数据!P:P,"<"&X90*1.2) -> 0 | AY90: =COUNTIFS(拍卖数据!E:E,AA90,拍卖数据!F:F,AB90,拍卖数据!O:O,O90,拍卖数据!AN:AN,"机构",拍卖数据!P:P,">"&X90*0.8,拍卖数据!P:P,"<"&X90*1.2) -> 0 | AZ90: =COUNTIFS(拍卖数据!E:E,AA90,拍卖数据!F:F,AB90,拍卖数据!G:G,AC90,拍卖数据!O:O,O90,拍卖数据!AN:AN,"机构",拍卖数据!P:P,">"&X90*0.8,拍卖数据!P:P,"<"&X90*1.2) -> 0
A91: 7798 | B91: 12230013026400000001 | C91: 否 | D91: 五河县双丰面粉有限公司 | E91: 小麦加工 | F91: 400 | G91: 750.80494 | H91: 0 | I91: 0 | J91: 1150.8049 | K91: 抵押,质押,保证 | L91: 武怀兰,王庆伟,王玉亮,蚌埠融资担保集团有限公司 | M91: 332 | N91: 现房 | O91: 工业用房 | P91: 标准工业厂房及仓储 | Q91: 新建 | R91: 五河县双丰面粉有限公司 | S91: 913403228501646423 | T91: 01012025091430238 | U91: 五河县武桥镇界沟村（104国道东侧)房地权五公字第212053-3号 | V91: 房他证五公字第212053-3号 | W91: 2061/3/31 | X91: 2340 | Y91: 平方米 | Z91: 是 | AA91: 安徽省 | AB91: 蚌埠市 | AC91: 五河县 | AD91: 五河县武桥镇界沟村（104国道东侧) | AE91: 第一顺位 | AF91: 330 | AG91: 外部评估 | AH91: 45071 | AI91: 257.4 | AJ91: 否 | AL91: 不涉及 | AM91: 0 | AO91: 张乐群,曹吉峰,董俣顺,许之玮,邹熠峰,郑舒凌 | AP91: 安徽分公司 | AQ91: 12230013 | AR91: 收购徽商银行2023年第2批133户不良资产包项目 | AS91: 45170 | AU91: 11001 | AV91: 已剔重 | AX91: =COUNTIFS(拍卖数据!E:E,AA91,拍卖数据!F:F,AB91,拍卖数据!O:O,O91,拍卖数据!P:P,">"&X91*0.8,拍卖数据!P:P,"<"&X91*1.2) -> 2 | AY91: =COUNTIFS(拍卖数据!E:E,AA91,拍卖数据!F:F,AB91,拍卖数据!O:O,O91,拍卖数据!AN:AN,"机构",拍卖数据!P:P,">"&X91*0.8,拍卖数据!P:P,"<"&X91*1.2) -> 2 | AZ91: =COUNTIFS(拍卖数据!E:E,AA91,拍卖数据!F:F,AB91,拍卖数据!G:G,AC91,拍卖数据!O:O,O91,拍卖数据!AN:AN,"机构",拍卖数据!P:P,">"&X91*0.8,拍卖数据!P:P,"<"&X91*1.2) -> 0
A92: 7799 | B92: 12230013026400000001 | C92: 否 | D92: 五河县双丰面粉有限公司 | E92: 小麦加工 | F92: 400 | G92: 750.80494 | H92: 0 | I92: 0 | J92: 1150.8049 | K92: 抵押,质押,保证 | L92: 武怀兰,王庆伟,王玉亮,蚌埠融资担保集团有限公司 | M92: 332 | N92: 土地使用权 | O92: 工业用地 | P92: 工业用地 | Q92: 新建 | R92: 五河县双丰面粉有限公司 | S92: 913403228501646423 | T92: 01022025091430006 | U92: 五河县武桥镇界沟村（104国道东侧)五国用（2011）第2102号 | V92: 五他项（2014）第088号 | W92: 2061/3/31 | X92: 6671 | Y92: 平方米 | Z92: 是 | AA92: 安徽省 | AB92: 蚌埠市 | AC92: 五河县 | AD92: 五河县武桥镇界沟村（104国道东侧) | AE92: 第一顺位 | AF92: 70 | AG92: 外部评估 | AH92: 45071 | AI92: 60.04 | AJ92: 否 | AL92: 不涉及 | AO92: 张乐群,曹吉峰,董俣顺,许之玮,邹熠峰,郑舒凌 | AP92: 安徽分公司 | AQ92: 12230013 | AR92: 收购徽商银行2023年第2批133户不良资产包项目 | AS92: 45170 | AU92: 11001 | AV92: 已剔重 | AX92: =COUNTIFS(拍卖数据!E:E,AA92,拍卖数据!F:F,AB92,拍卖数据!O:O,O92,拍卖数据!P:P,">"&X92*0.8,拍卖数据!P:P,"<"&X92*1.2) -> 0 | AY92: =COUNTIFS(拍卖数据!E:E,AA92,拍卖数据!F:F,AB92,拍卖数据!O:O,O92,拍卖数据!AN:AN,"机构",拍卖数据!P:P,">"&X92*0.8,拍卖数据!P:P,"<"&X92*1.2) -> 0 | AZ92: =COUNTIFS(拍卖数据!E:E,AA92,拍卖数据!F:F,AB92,拍卖数据!G:G,AC92,拍卖数据!O:O,O92,拍卖数据!AN:AN,"机构",拍卖数据!P:P,">"&X92*0.8,拍卖数据!P:P,"<"&X92*1.2) -> 0
A93: 7800 | B93: 12230013026400000001 | C93: 否 | D93: 五河县双丰面粉有限公司 | E93: 小麦加工 | F93: 400 | G93: 750.80494 | H93: 0 | I93: 0 | J93: 1150.8049 | K93: 抵押,质押,保证 | L93: 武怀兰,王庆伟,王玉亮,蚌埠融资担保集团有限公司 | M93: 332 | N93: 现房 | O93: 工业用房 | P93: 标准工业厂房及仓储 | Q93: 新建 | R93: 五河县双丰面粉有限公司 | S93: 913403228501646423 | T93: 01012025091430239 | U93: 五河县武桥镇界沟村（104国道东侧)房地权五公字第212053-4号 | V93: 房他证五公字第212053-4号 | W93: 2061/3/31 | X93: 2757.2 | Y93: 平方米 | Z93: 是 | AA93: 安徽省 | AB93: 蚌埠市 | AC93: 五河县 | AD93: 五河县武桥镇界沟村（104国道东侧) | AE93: 第一顺位 | AF93: 330 | AG93: 外部评估 | AH93: 45071 | AI93: 303.29 | AJ93: 否 | AL93: 不涉及 | AM93: 0 | AO93: 张乐群,曹吉峰,董俣顺,许之玮,邹熠峰,郑舒凌 | AP93: 安徽分公司 | AQ93: 12230013 | AR93: 收购徽商银行2023年第2批133户不良资产包项目 | AS93: 45170 | AU93: 11001 | AV93: 已剔重 | AX93: =COUNTIFS(拍卖数据!E:E,AA93,拍卖数据!F:F,AB93,拍卖数据!O:O,O93,拍卖数据!P:P,">"&X93*0.8,拍卖数据!P:P,"<"&X93*1.2) -> 3 | AY93: =COUNTIFS(拍卖数据!E:E,AA93,拍卖数据!F:F,AB93,拍卖数据!O:O,O93,拍卖数据!AN:AN,"机构",拍卖数据!P:P,">"&X93*0.8,拍卖数据!P:P,"<"&X93*1.2) -> 2 | AZ93: =COUNTIFS(拍卖数据!E:E,AA93,拍卖数据!F:F,AB93,拍卖数据!G:G,AC93,拍卖数据!O:O,O93,拍卖数据!AN:AN,"机构",拍卖数据!P:P,">"&X93*0.8,拍卖数据!P:P,"<"&X93*1.2) -> 0
A94: 12217 | B94: 12253005010006 | C94: 否 | D94: 六安市东怡商贸有限公司 | E94: 批发和零售业 | F94: 1445 | G94: 1277.0939 | H94: 10.5 | J94: 2732.5939 | K94: 抵押,保证 | L94: 刘幼红,刘幼红,王庆淮,王庆淮,王敬雪,王敬雪 | M94: 840.96301 | N94: 现房 | O94: 商业用房 | P94: 集中商业（购物中心，综合体商业等） | Q94: 已入库 | R94: 六安市东川房地产开发有限责任公司 | S94: 91341500584562612K | T94: 01012025071130001 | U94: 御财广场商业房产一层 | V94: 皖（2018）六安市不动产证明第3044958号 | W94: 2051-09-23 | X94: 1036.41 | Y94: 平方米 | Z94: 是 | AA94: 安徽省 | AB94: 六安市 | AC94: 金安区 | AD94: 正阳路以西纬三路以北御财广场项目 | AE94: 第零顺位 | AF94: 920 | AG94: 外部评估 | AH94: 45776 | AI94: 804.67 | AJ94: 否 | AL94: 不涉及 | AM94: 0 | AO94: 许之玮,陈文轩 | AP94: 安徽分公司 | AQ94: 12253005 | AR94: 收购九江银行合肥分行2025年第1批3户不良资产包项目 | AS94: 45834 | AU94: 11000 | AV94: 已剔重 | AX94: =COUNTIFS(拍卖数据!E:E,AA94,拍卖数据!F:F,AB94,拍卖数据!O:O,O94,拍卖数据!P:P,">"&X94*0.8,拍卖数据!P:P,"<"&X94*1.2) -> 0 | AY94: =COUNTIFS(拍卖数据!E:E,AA94,拍卖数据!F:F,AB94,拍卖数据!O:O,O94,拍卖数据!AN:AN,"机构",拍卖数据!P:P,">"&X94*0.8,拍卖数据!P:P,"<"&X94*1.2) -> 0 | AZ94: =COUNTIFS(拍卖数据!E:E,AA94,拍卖数据!F:F,AB94,拍卖数据!G:G,AC94,拍卖数据!O:O,O94,拍卖数据!AN:AN,"机构",拍卖数据!P:P,">"&X94*0.8,拍卖数据!P:P,"<"&X94*1.2) -> 0
A95: 12218 | B95: 12253005010006 | C95: 否 | D95: 六安市东怡商贸有限公司 | E95: 批发和零售业 | F95: 1445 | G95: 1277.0939 | H95: 10.5 | J95: 2732.5939 | K95: 抵押,保证 | L95: 刘幼红,刘幼红,王庆淮,王庆淮,王敬雪,王敬雪 | M95: 840.96301 | N95: 现房 | O95: 商业用房 | P95: 集中商业（购物中心，综合体商业等） | Q95: 已入库 | R95: 六安市东川房地产开发有限责任公司 | S95: 91341500584562612K | T95: 01012025071130002 | U95: 御财广场商业房产二层 | V95: 皖（2018）六安市不动产证明第3044959号 | W95: 2051-09-23 | X95: 1027.42 | Y95: 平方米 | Z95: 是 | AA95: 安徽省 | AB95: 六安市 | AC95: 金安区 | AD95: 正阳路以西纬三路以北御财广场项目 | AE95: 第零顺位 | AF95: 530 | AG95: 外部评估 | AH95: 45776 | AI95: 478.57 | AJ95: 否 | AL95: 不涉及 | AM95: 0 | AO95: 许之玮,陈文轩 | AP95: 安徽分公司 | AQ95: 12253005 | AR95: 收购九江银行合肥分行2025年第1批3户不良资产包项目 | AS95: 45834 | AU95: 11000 | AV95: 已剔重 | AX95: =COUNTIFS(拍卖数据!E:E,AA95,拍卖数据!F:F,AB95,拍卖数据!O:O,O95,拍卖数据!P:P,">"&X95*0.8,拍卖数据!P:P,"<"&X95*1.2) -> 0 | AY95: =COUNTIFS(拍卖数据!E:E,AA95,拍卖数据!F:F,AB95,拍卖数据!O:O,O95,拍卖数据!AN:AN,"机构",拍卖数据!P:P,">"&X95*0.8,拍卖数据!P:P,"<"&X95*1.2) -> 0 | AZ95: =COUNTIFS(拍卖数据!E:E,AA95,拍卖数据!F:F,AB95,拍卖数据!G:G,AC95,拍卖数据!O:O,O95,拍卖数据!AN:AN,"机构",拍卖数据!P:P,">"&X95*0.8,拍卖数据!P:P,"<"&X95*1.2) -> 0
A96: 12219 | B96: 12240053002700000001 | C96: 否 | D96: 六安市星星矿业有限公司 | E96: 其他非金属矿物制品制造 | F96: 500 | G96: 324.90137 | H96: 2.12 | I96: 0 | J96: 827.02137 | K96: 抵押,质押,保证 | L96: 郭旭东,马艳 | M96: 172.44 | N96: 现房 | O96: 商业用房 | P96: 集中商业（购物中心，综合体商业等） | Q96: 新建 | R96: 郭旭东 | S96: 342401196801262218 | T96: 01012025091430112 | U96: 六安市经济开发区上东·阳光城10号楼5铺(1-2层）皖（2017）六安市市不动产权第0066160号 | V96: 皖（2018）六安市市不动产证明第3055340号 | W96: 2047/10/20 | X96: 124.13 | Y96: 平方米 | Z96: 是 | AA96: 安徽省 | AB96: 六安市 | AC96: 金安区 | AD96: 六安市经济开发区上东·阳光城10号楼5铺(1-2层） | AE96: 第一顺位 | AF96: 95 | AG96: 外部评估 | AH96: 45558 | AI96: 101.79 | AJ96: 否 | AL96: 不涉及 | AO96: 张乐群,曹吉峰,董俣顺,许之玮,邹熠峰,郑舒凌 | AP96: 安徽分公司 | AQ96: 12240053 | AR96: 收购颍东农商行2024年第1批12户不良资产包项目 | AS96: 45587 | AU96: 11001 | AV96: 已剔重 | AX96: =COUNTIFS(拍卖数据!E:E,AA96,拍卖数据!F:F,AB96,拍卖数据!O:O,O96,拍卖数据!P:P,">"&X96*0.8,拍卖数据!P:P,"<"&X96*1.2) -> 7 | AY96: =COUNTIFS(拍卖数据!E:E,AA96,拍卖数据!F:F,AB96,拍卖数据!O:O,O96,拍卖数据!AN:AN,"机构",拍卖数据!P:P,">"&X96*0.8,拍卖数据!P:P,"<"&X96*1.2) -> 0 | AZ96: =COUNTIFS(拍卖数据!E:E,AA96,拍卖数据!F:F,AB96,拍卖数据!G:G,AC96,拍卖数据!O:O,O96,拍卖数据!AN:AN,"机构",拍卖数据!P:P,">"&X96*0.8,拍卖数据!P:P,"<"&X96*1.2) -> 0
A97: 12220 | B97: 12240053002700000001 | C97: 否 | D97: 六安市星星矿业有限公司 | E97: 其他非金属矿物制品制造 | F97: 500 | G97: 324.90137 | H97: 2.12 | I97: 0 | J97: 827.02137 | K97: 抵押,质押,保证 | L97: 郭旭东,马艳 | M97: 172.44 | N97: 现房 | O97: 商业用房 | P97: 集中商业（购物中心，综合体商业等） | Q97: 新建 | R97: 郭旭东 | S97: 342401196801262218 | T97: 01012025091430122 | U97: 六安市经济开发区上东·阳光城13号楼二层12铺皖（2017）六安市市不动产权第0066165号 | V97: 皖（2018）六安市市不动产证明第3055337号 | W97: 2047/10/20 | X97: 74.57 | Y97: 平方米 | Z97: 是 | AA97: 安徽省 | AB97: 六安市 | AC97: 金安区 | AD97: 六安市经济开发区上东·阳光城13号楼二层12铺 | AE97: 第一顺位 | AF97: 40 | AG97: 外部评估 | AH97: 45558 | AI97: 26.85 | AJ97: 否 | AL97: 不涉及 | AO97: 张乐群,曹吉峰,董俣顺,许之玮,邹熠峰,郑舒凌 | AP97: 安徽分公司 | AQ97: 12240053 | AR97: 收购颍东农商行2024年第1批12户不良资产包项目 | AS97: 45587 | AU97: 11001 | AV97: 已剔重 | AX97: =COUNTIFS(拍卖数据!E:E,AA97,拍卖数据!F:F,AB97,拍卖数据!O:O,O97,拍卖数据!P:P,">"&X97*0.8,拍卖数据!P:P,"<"&X97*1.2) -> 2 | AY97: =COUNTIFS(拍卖数据!E:E,AA97,拍卖数据!F:F,AB97,拍卖数据!O:O,O97,拍卖数据!AN:AN,"机构",拍卖数据!P:P,">"&X97*0.8,拍卖数据!P:P,"<"&X97*1.2) -> 0 | AZ97: =COUNTIFS(拍卖数据!E:E,AA97,拍卖数据!F:F,AB97,拍卖数据!G:G,AC97,拍卖数据!O:O,O97,拍卖数据!AN:AN,"机构",拍卖数据!P:P,">"&X97*0.8,拍卖数据!P:P,"<"&X97*1.2) -> 0
A98: 12221 | B98: 12240053002700000001 | C98: 否 | D98: 六安市星星矿业有限公司 | E98: 其他非金属矿物制品制造 | F98: 500 | G98: 324.90137 | H98: 2.12 | I98: 0 | J98: 827.02137 | K98: 抵押,质押,保证 | L98: 郭旭东,马艳 | M98: 172.44 | N98: 现房 | O98: 商业用房 | P98: 集中商业（购物中心，综合体商业等） | Q98: 新建 | R98: 郭旭东 | S98: 342401196801262218 | T98: 01012025091430121 | U98: 六安市经济开发区上东·阳光城13号楼二层11铺皖（2017）六安市市不动产权第0066169号 | V98: 皖（2018）六安市市不动产证明第3055335号 | W98: 2047/10/20 | X98: 79.9 | Y98: 平方米 | Z98: 是 | AA98: 安徽省 | AB98: 六安市 | AC98: 金安区 | AD98: 六安市经济开发区上东·阳光城13号楼二层11铺 | AE98: 第一顺位 | AF98: 45 | AG98: 外部评估 | AH98: 45558 | AI98: 28.76 | AJ98: 否 | AL98: 不涉及 | AO98: 张乐群,曹吉峰,董俣顺,许之玮,邹熠峰,郑舒凌 | AP98: 安徽分公司 | AQ98: 12240053 | AR98: 收购颍东农商行2024年第1批12户不良资产包项目 | AS98: 45587 | AU98: 11001 | AV98: 已剔重 | AX98: =COUNTIFS(拍卖数据!E:E,AA98,拍卖数据!F:F,AB98,拍卖数据!O:O,O98,拍卖数据!P:P,">"&X98*0.8,拍卖数据!P:P,"<"&X98*1.2) -> 3 | AY98: =COUNTIFS(拍卖数据!E:E,AA98,拍卖数据!F:F,AB98,拍卖数据!O:O,O98,拍卖数据!AN:AN,"机构",拍卖数据!P:P,">"&X98*0.8,拍卖数据!P:P,"<"&X98*1.2) -> 0 | AZ98: =COUNTIFS(拍卖数据!E:E,AA98,拍卖数据!F:F,AB98,拍卖数据!G:G,AC98,拍卖数据!O:O,O98,拍卖数据!AN:AN,"机构",拍卖数据!P:P,">"&X98*0.8,拍卖数据!P:P,"<"&X98*1.2) -> 0
A99: 12222 | B99: 12240053002700000001 | C99: 否 | D99: 六安市星星矿业有限公司 | E99: 其他非金属矿物制品制造 | F99: 500 | G99: 324.90137 | H99: 2.12 | I99: 0 | J99: 827.02137 | K99: 抵押,质押,保证 | L99: 郭旭东,马艳 | M99: 172.44 | N99: 现房 | O99: 商业用房 | P99: 集中商业（购物中心，综合体商业等） | Q99: 新建 | R99: 郭旭东 | S99: 342401196801262218 | T99: 01012025091430120 | U99: 六安市经济开发区上东·阳光城13号楼二层10铺皖（2017）六安市市不动产权第0066168号 | V99: 皖（2018）六安市市不动产证明第3055334号 | W99: 2047/10/20 | X99: 61.89 | Y99: 平方米 | Z99: 是 | AA99: 安徽省 | AB99: 六安市 | AC99: 金安区 | AD99: 六安市经济开发区上东·阳光城13号楼二层10铺 | AE99: 第一顺位 | AF99: 35 | AG99: 外部评估 | AH99: 45558 | AI99: 22.28 | AJ99: 否 | AL99: 不涉及 | AO99: 张乐群,曹吉峰,董俣顺,许之玮,邹熠峰,郑舒凌 | AP99: 安徽分公司 | AQ99: 12240053 | AR99: 收购颍东农商行2024年第1批12户不良资产包项目 | AS99: 45587 | AU99: 11001 | AV99: 已剔重 | AX99: =COUNTIFS(拍卖数据!E:E,AA99,拍卖数据!F:F,AB99,拍卖数据!O:O,O99,拍卖数据!P:P,">"&X99*0.8,拍卖数据!P:P,"<"&X99*1.2) -> 0 | AY99: =COUNTIFS(拍卖数据!E:E,AA99,拍卖数据!F:F,AB99,拍卖数据!O:O,O99,拍卖数据!AN:AN,"机构",拍卖数据!P:P,">"&X99*0.8,拍卖数据!P:P,"<"&X99*1.2) -> 0 | AZ99: =COUNTIFS(拍卖数据!E:E,AA99,拍卖数据!F:F,AB99,拍卖数据!G:G,AC99,拍卖数据!O:O,O99,拍卖数据!AN:AN,"机构",拍卖数据!P:P,">"&X99*0.8,拍卖数据!P:P,"<"&X99*1.2) -> 0
...

Sheet Sheet1
B2: 要求：
B3: 发邮件，点击链接跳转
